Workbook

Sheet 封面1

Sheet 封面2

Sheet 目录
B2: 数字化身心健康评估报告目录
B4: Nutrition and Wellness Assessment Report
B6: 报告日期：2026年4月2日
B8: 本报告基于生物反馈检测数据，反应值仅供参考，不作为医学诊断依据。
B10: 数据标注说明（除基本体质外）：
B11: 黄色背景 | C11: 反应值 ≥ 100
B12: 红色背景 | C12: 反应值 ≤ 50
B14: 报告内容索引：
B15: 1、身体基本体质评估报告
B16: 2、氨基酸平衡性评估报告
B17: 3、矿物质平衡性评估报告
B18: 4、芳香疗法反应性评估报告
B19: 5、脊柱系统反应性评估报告
B20: 6、水溶性维生素平衡评估报告
B21: 7、脂溶性维生素平衡评估报告
B22: 8、一般消化系统评估报告
B23: 9、碳水化合物代谢反应性评估报告
B24: 10、蛋白质和脂类代谢反应性评估报告
B25: 11、外源性物质反应性评估报告
... B32: 注：反应值高于100表示高反应，低于50表示低反应。高反应可能表示压力或负担，低反应可能表示不足或缺乏。

Sheet 总结建议
B1: 数字化身心健康评估及总结
B2: 综合压力指数： | D2: 25430 | E2: （高压力状态） | G2: =_xlfn.XLOOKUP(E2,Sheet1!B20:B23,Sheet1!C20:C23,"无匹配") -> 呈现平静无感或明显紧绷的两极状态，身心持续耗损，难以彻底放松
B3: 您的基本体质：
B4: 1 | C4: 体力 | D4: ◉ 正常
B5: 2 | C5: 脑力 | D5: ◉ 偏弱
B6: 3 | C6: 免疫力 | D6: ◉ 慢性压力
B7: 4 | C7: 水合 | D7: ◉ 偏弱
B8: 5 | C8: 氧化 | D8: ◉ 正常
B10: 需重点关注：
B11: ✅ 微量元素失衡：易引发疲劳乏力、免疫力降低、睡眠变差、肌肉不适及代谢紊乱等亚健康问题。
B12: ✅ 肠道菌群紊乱：易引发消化问题、代谢异常，影响情绪与免疫，增加焦虑、炎症及心脑血管风险。
B13: ✅ 情绪波动较大：易扰乱内分泌、减慢毒素代谢、损伤胃肠消化，并加重失眠乏力与脊柱神经紧张。
B14: ✅ 胆固醇代谢异常：易在血管沉积引发动脉硬化，损伤脑部神经与认知功能，引发头痛、失眠等问题。
B16: 标识提示：
B17: ◉ 明显失衡 | D17: ◉ 中度失衡 | E17: ◉ 轻度失衡 | G17: ◉ 健康状态
B18: ◉ 明显失衡状态，需要立即引起重视，避免发展成为疾病。
B19: ◉ 中度失衡状态，不适症状较明显，需系统改善身体状态。
B20: ◉ 轻度失衡状态，身体出现轻微不适，及时调整可快速恢复。
B21: ◉ 健康状态，身体机能运转良好，保持现有习惯即可持续维持。
B23: 序号 | C23: 报告类型 | E23: 健康标识 | F23: 电生理特征 | H23: 可能的表现 | I23: 改善建议
B24: 1 | C24: 基本体质 | E24: ◉ | F24: 轻度失衡状态 | H24: {=_xlfn.XLOOKUP(F24,Sheet1!$G$19:$J$19,Sheet1!G20:J20,"无匹配")} -> 易累犯困，恢复偏慢 | I24: {=_xlfn.IFS(F24=Sheet1!$G$19,Sheet1!L20,OR(F24=Sheet1!$H$19,F24=Sheet1!$I$19,F24=Sheet1!$K$19),Sheet1!K20,TRUE,"")} -> 规律作息 / 运动 / 复合维生素
B25: 2 | C25: 脊椎神经系统 | E25: ◉ | F25: 中度失衡状态 | H25: {=_xlfn.XLOOKUP(F25,Sheet1!$G$19:$J$19,Sheet1!G21:J21,"无匹配")} -> 颈肩酸痛，偶发麻木 | I25: {=_xlfn.IFS(F25=Sheet1!$G$19,Sheet1!L21,OR(F25=Sheet1!$H$19,F25=Sheet1!$I$19,F25=Sheet1!$K$19),Sheet1!K21,TRUE,"")} -> 脊柱放松矫正 / 三向量训练
B26: 3 | C26: 氨基酸 | E26: ◉ | F26: 轻度失衡状态 | H26: {=_xlfn.XLOOKUP(F26,Sheet1!$G$19:$J$19,Sheet1!G22:J22,"无匹配")} -> 代谢偏弱，偶感疲惫 | I26: {=_xlfn.IFS(F26=Sheet1!$G$19,Sheet1!L22,OR(F26=Sheet1!$H$19,F26=Sheet1!$I$19,F26=Sheet1!$K$19),Sheet1!K22,TRUE,"")} -> 足量优质蛋白/规律作息/适度运动
B27: 4 | C27: 矿物质 | E27: ◉ | F27: 中度失衡状态 | H27: {=_xlfn.XLOOKUP(F27,Sheet1!$G$19:$J$19,Sheet1!G23:J23,"无匹配")} -> 腰膝酸软，易发抽筋 | I27: {=_xlfn.IFS(F27=Sheet1!$G$19,Sheet1!L23,OR(F27=Sheet1!$H$19,F27=Sheet1!$I$19,F27=Sheet1!$K$19),Sheet1!K23,TRUE,"")} -> 拉伸放松 / 矿物质补充 / 多维调理
B28: 5 | C28: 芳香疗法 | E28: ◉ | F28: 健康状态 | H28: {=_xlfn.XLOOKUP(F28,Sheet1!$G$19:$J$19,Sheet1!G24:J24,"无匹配")} -> 气息调和，身心舒缓 | I28: {=_xlfn.IFS(F28=Sheet1!$G$19,Sheet1!L24,OR(F28=Sheet1!$H$19,F28=Sheet1!$I$19,F28=Sheet1!$K$19),Sheet1!K24,TRUE,"")} -> 继续保持
B29: 6 | C29: 水溶性维生素 | E29: ◉ | F29: 轻度失衡状态 | H29: {=_xlfn.XLOOKUP(F29,Sheet1!$G$19:$J$19,Sheet1!G25:J25,"无匹配")} -> 微量缺乏，偶有不适 | I29: {=_xlfn.IFS(F29=Sheet1!$G$19,Sheet1!L25,OR(F29=Sheet1!$H$19,F29=Sheet1!$I$19,F29=Sheet1!$K$19),Sheet1!K25,TRUE,"")} -> 新鲜果蔬/均衡饮食/每日补水
B30: 7 | C30: 脂溶性维生素 | E30: ◉ | F30: 健康状态 | H30: {=_xlfn.XLOOKUP(F30,Sheet1!$G$19:$J$19,Sheet1!G26:J26,"无匹配")} -> 储备充足，吸收良好 | I30: {=_xlfn.IFS(F30=Sheet1!$G$19,Sheet1!L26,OR(F30=Sheet1!$H$19,F30=Sheet1!$I$19,F30=Sheet1!$K$19),Sheet1!K26,TRUE,"")} -> 继续保持
B31: 8 | C31: 一般消化系统 | E31: ◉ | F31: 中度失衡状态 | H31: {=_xlfn.XLOOKUP(F31,Sheet1!$G$19:$J$19,Sheet1!G27:J27,"无匹配")} -> 时常反酸，肠胃敏感 | I31: {=_xlfn.IFS(F31=Sheet1!$G$19,Sheet1!L27,OR(F31=Sheet1!$H$19,F31=Sheet1!$I$19,F31=Sheet1!$K$19),Sheet1!K27,TRUE,"")} -> 少食刺激/少食多餐/饭后散步
B32: 9 | C32: 碳水化合物代谢 | E32: ◉ | F32: 健康状态 | H32: {=_xlfn.XLOOKUP(F32,Sheet1!$G$19:$J$19,Sheet1!G28:J28,"无匹配")} -> 供能平稳，血糖稳定 | I32: {=_xlfn.IFS(F32=Sheet1!$G$19,Sheet1!L28,OR(F32=Sheet1!$H$19,F32=Sheet1!$I$19,F32=Sheet1!$K$19),Sheet1!K28,TRUE,"")} -> 继续保持
B33: 10 | C33: 蛋白质和脂类代谢 | E33: ◉ | F33: 轻度失衡状态 | H33: {=_xlfn.XLOOKUP(F33,Sheet1!$G$19:$J$19,Sheet1!G29:J29,"无匹配")} -> 代谢缓慢，易水肿乏力 | I33: {=_xlfn.IFS(F33=Sheet1!$G$19,Sheet1!L29,OR(F33=Sheet1!$H$19,F33=Sheet1!$I$19,F33=Sheet1!$K$19),Sheet1!K29,TRUE,"")} -> 优质蛋白/少油饮食/力量训练
B34: 11 | C34: 外源性物质 | E34: ◉ | F34: 健康状态 | H34: {=_xlfn.XLOOKUP(F34,Sheet1!$G$19:$J$19,Sheet1!G30:J30,"无匹配")} -> 代谢清除顺畅无蓄积 | I34: {=_xlfn.IFS(F34=Sheet1!$G$19,Sheet1!L30,OR(F34=Sheet1!$H$19,F34=Sheet1!$I$19,F34=Sheet1!$K$19),Sheet1!K30,TRUE,"")} -> 继续保持
B35: 12 | C35: 外源性物质额外因素 | E35: ◉ | F35: 中度失衡状态 | H35: {=_xlfn.XLOOKUP(F35,Sheet1!$G$19:$J$19,Sheet1!G31:J31,"无匹配")} -> 多重外源刺激加重负担 | I35: {=_xlfn.IFS(F35=Sheet1!$G$19,Sheet1!L31,OR(F35=Sheet1!$H$19,F35=Sheet1!$I$19,F35=Sheet1!$K$19),Sheet1!K31,TRUE,"")} -> 规避香精添加剂/减少环境刺激
... B39: 16 | C39: 神经递质 | E39: ◉ | F39: 轻度失衡状态 | H39: {=_xlfn.XLOOKUP(F39,Sheet1!$G$19:$J$19,Sheet1!G35:J35,"无匹配")} -> 分泌轻微失衡，专注力下降 | I39: {=_xlfn.IFS(F39=Sheet1!$G$19,Sheet1!L35,OR(F39=Sheet1!$H$19,F39=Sheet1!$I$19,F39=Sheet1!$K$19),Sheet1!K35,TRUE,"")} -> 优质蛋白/B 族维生素/舒缓运动
B41: 方案建议：
B42: 以轻量阶段式方案为主，营养补充和物理辅助调理结合，生活方式调整及运动。

Sheet 健康管理方案
B2: OMNIS身心综合健康管理方案
B3: OMNIS Comprehensive Mind-Body Health Management Plan
B5: （一）OMNIS/QUEX 身心压力专项调理方案
C6: 通过Biofeedback进行调理训练 | D6: 8次 | E6: （2次/周）
B7: ✅ | C7: 消化系统、综合代谢调理 | F7: ✅ | G7: 放松调理(释放隐藏情绪)
C8: {=INDIRECT("Sheet1!B"&MATCH(健康管理方案!C7,Sheet1!A:A,0))} -> =DISPIMG("ID_93EBEE16CCCD4557A7DB6EF80C77801C",1) | G8: {=INDIRECT("Sheet1!B"&MATCH(G7,Sheet1!A:A,0))} -> =DISPIMG("ID_3EC9A1FB2472459B88FB10F552D3FF5E",1)
B9: ✅ | C9: 消化酶、营养吸收促进调理 | F9: ✅ | G9: 消化酶、营养吸收促进调理
C10: {=INDIRECT("Sheet1!B"&MATCH(健康管理方案!C9,Sheet1!A:A,0))} -> =DISPIMG("ID_1B2270656ACC4FE28D9A81DEEA59A05D",1) | G10: {=INDIRECT("Sheet1!B"&MATCH(G9,Sheet1!A:A,0))} -> =DISPIMG("ID_1B2270656ACC4FE28D9A81DEEA59A05D",1)
B11: ✅ | C11: 消化系统、综合代谢调理 | F11: ✅ | G11: 消化系统、综合代谢调理
C12: {=INDIRECT("Sheet1!B"&MATCH(健康管理方案!C11,Sheet1!A:A,0))} -> =DISPIMG("ID_93EBEE16CCCD4557A7DB6EF80C77801C",1) | G12: {=INDIRECT("Sheet1!B"&MATCH(G11,Sheet1!A:A,0))} -> =DISPIMG("ID_93EBEE16CCCD4557A7DB6EF80C77801C",1)
B13: ✅ | C13: 消化系统、综合代谢调理 | F13: ✅ | G13: 消化系统、综合代谢调理
C14: {=INDIRECT("Sheet1!B"&MATCH(健康管理方案!C13,Sheet1!A:A,0))} -> =DISPIMG("ID_93EBEE16CCCD4557A7DB6EF80C77801C",1) | G14: {=INDIRECT("Sheet1!B"&MATCH(G13,Sheet1!A:A,0))} -> =DISPIMG("ID_93EBEE16CCCD4557A7DB6EF80C77801C",1)
B15: （二）压力管理与心理调适方案
B16: ✅ | C16: 情绪心理压力深度咨询 | D16: 4次 | E16: （1次/2周）
C17: 国家二级心理咨询师1V1咨询，每次50-60分钟，提升情绪认知水平。
B18: ✅ | C18: 居家压力管理（可每日进行）：
C19: 学习应对和管理压力的技巧，如深呼吸、冥想、放松技巧或寻求支持和建议。 保持积极的心态，避免长期处于紧张、焦虑或抑郁状态。
B20: （三）营养与饮食建议
B21: ✅ | C21: 膳食营养补充剂建议
C22: 益生菌 | F22: GABA氨基丁酸
C23: 深海鱼油 | F23: 甘氨酸镁剂
C24: 卵磷脂 | F24: B族维生素
C25: 综合消化酶 | F25: 多种矿物质
B26: ✅ | C26: 日常生活饮食建议
C27: 食物多样化，确保摄入全面的营养。多吃新鲜蔬果、大豆和坚果，它们富含维生素、矿物质和膳食纤维。适量摄入魚、禽、蛋和瘦肉，提供优质蛋白质、维生素和矿物质。控制盐、油、糖的摄入量。饮最少8杯清水，不能等到口渴时才喝水。限制酒精摄入，避免过量饮酒对身体和心理健康造成损害。
C28: 尽量减少猪肉、乳制品、咖啡因等物质的摄入，避免毒素堆积。
C29: 尽量避免不耐受⻝物：不耐受食物请参考相应数据报告。
B30: （四）生活方式建议
B31: ✅ | C31: 规律运动
C32: 找到适合自己的运动方式，适量增加力量训练，以增强肌肉和骨骼。 运动有助于增强心肺功能、控制体重、促进新陈代谢，有助于心理健康。
B33: ✅ | C33: 充足睡眠
C34: 确保有规律的作息时间和一个舒适的睡眠环境。确保6至8小时睡眠。 充足的睡眠有助于减缓衰老、预防内分泌紊乱和失眠，对身心健康都有益处。
B35: 标准化调理流程（严格遵循QXworld 官方操作规范）
B36: ✅ | C36: 静心准备（5 分钟）：评估当日状态，设定调理目标，佩戴专用检测设备，引导放松与连接。
B37: ✅ | C37: 扫描检测（3 分钟）：运行专项扫检测程序，锁定核心失衡点，动态调整个性化调理方案。
B38: ✅ | C38: 辅助调理（40-60 分钟）：实时监测身体反应，动态优化参数，确保调理效果稳定达标。
B39: ✅ | C39: 能量整合（5 分钟）：平衡身体能量状态，引导身心落地整合。
B40: ✅ | C40: 总结建议（10-15 分钟）：对比调理前后数据，解读改善指标，给到居家执行建议。
B42: 分阶段预期效果（基于1000 + 临床案例验证）
B43: ✅ | C43: 密集调理期（1-4周）：不适感减轻40%-60%，自主神经失衡状态改善，压力水平趋向正常反应值。
...

Sheet Sheet1
A1: 名字 | B1: 图片
A2: 消化系统、综合代谢调理 | B2: =_xlfn.DISPIMG("ID_93EBEE16CCCD4557A7DB6EF80C77801C",1) -> =DISPIMG("ID_93EBEE16CCCD4557A7DB6EF80C77801C",1) | F2: ✅ 微量元素失衡：易引发疲劳乏力、免疫力降低、睡眠变差、肌肉不适及代谢紊乱等亚健康问题。
A3: 消化酶、营养吸收促进调理 | B3: =_xlfn.DISPIMG("ID_1B2270656ACC4FE28D9A81DEEA59A05D",1) -> =DISPIMG("ID_1B2270656ACC4FE28D9A81DEEA59A05D",1) | F3: ✅ 脊椎神经系统失衡：易引发颈肩腰背酸痛僵硬、肢体麻木、头晕犯困，并影响内脏功能与睡眠情绪。
A4: 放松调理(释放隐藏情绪) | B4: =_xlfn.DISPIMG("ID_3EC9A1FB2472459B88FB10F552D3FF5E",1) -> =DISPIMG("ID_3EC9A1FB2472459B88FB10F552D3FF5E",1) | F4: ✅ 肠道菌群紊乱：易引发消化问题、代谢异常，影响情绪与免疫，增加焦虑、炎症及心脑血管风险。
A5: 慢性疲劳调理训练 | F5: ✅ 情绪波动较大：易扰乱内分泌、减慢毒素代谢、损伤胃肠消化，并加重失眠乏力与脊柱神经紧张。
A6: 线粒体功能平衡训练 | F6: ✅ 胃肠道功能失衡：易致营养吸收不足、毒素蓄积，进而诱发脂肪肝及全身亚健康问题。
A7: 甲状腺功能平衡调理训练 | F7: ✅ 情绪压力偏大：易引发心脑血管疾病、失眠抑郁、肠胃紊乱，降低免疫与内分泌失调。
A8: 新陈代谢提升调理 | F8: ✅ 胆固醇代谢异常：易在血管沉积引发动脉硬化，损伤脑部神经与认知功能，引发头痛、失眠等问题。
A9: 释放神经系统压力 | F9: ✅ 碳水化合物代谢异常：易引发胰岛素抵抗，引发肥胖、高血压、高脂血症等，增加心脑血管疾病风险。
A10: 自主神经系统平衡调理 | F10: ✅ 微量营养素失衡：易引发疲劳乏力、免疫力降低、睡眠变差、肌肉不适及代谢紊乱等亚健康问题。
A11: 睡眠专项调理 | F11: ✅ 甘油三脂代谢异常：易造成脂肪堆积肝脏、血液黏稠、身体沉重困倦，加重脂肪肝与全身代谢亚健康。
A12: 平衡免疫系统，修复炎症，缓解过敏反应 | F12: ✅ 隐藏情绪压力和近期压力较大：易扰乱内分泌、损伤胃肠消化，并加重失眠乏力与脊柱神经紧张。
A13: 肝脏代谢压力调理训练 | F13: ✅ 肝胆代谢失衡：解毒排毒能力下降，毒素堆积体内，诱发面色暗沉长痘、口苦烦躁、晨起疲惫、脂肪代谢受阻加重脂肪肝
A14: 脂代谢平衡训练 | F14: ✅ 气血循环不畅：供氧供血不足，手脚冰凉发麻、面色苍白发黄、心慌气短、记忆力衰退、久坐头晕。
F15: ✅ 血氧含量偏低：大脑供氧不足，整日昏沉健忘、注意力涣散、头部闷胀、深度睡眠严重不足。
F16: ✅ 雌激素水平紊乱：内分泌节律失调，经期紊乱痛经、乳腺胀痛、面部色斑滋生，情绪敏感易怒、减脂困难早衰
F17: ✅ 雄激素分泌失衡：油脂分泌旺盛、反复脱发长痘、腹部脂肪堆积，精神萎靡、睡眠浅易惊醒。
F19: 检测指标 | G19: 健康状态 | H19: 轻度失衡状态 | I19: 中度失衡状态 | J19: 重度失衡状态 | K19: 改善方案
A20: <=15000 | B20: （正常压力） | C20: 身心舒展，睡眠精力稳定，情绪平和不易心烦 | F20: 基本体质 | G20: 精力充沛，通体舒适 | H20: 易累犯困，恢复偏慢 | I20: 持续乏力，精神不振 | J20: 整日困倦，体力不支 | K20: 规律作息 / 运动 / 复合维生素 | L20: 继续保持
A21: <=2000,>15000 | B21: （轻微压力） | C21: 偶尔疲惫多虑，轻微肩颈发紧，放松后很快恢复 | F21: 脊柱神经系统 | G21: 脊柱舒适，无酸胀感 | H21: 久坐僵硬，活动缓解 | I21: 颈肩酸痛，偶发麻木 | J21: 僵硬明显，活动受限 | K21: 脊柱放松矫正 / 三向量训练 | L21: 继续保持
A22: <=2500,>20000 | B22: （压力较大） | C22: 时常睡不踏实、浑身酸胀，容易内耗，单纯休息难缓解 | F22: 氨基酸 | G22: 代谢均衡，身心舒适 | H22: 代谢偏弱，偶感疲惫 | I22: 代谢紊乱，持续乏力 | J22: 代谢阻滞，周身不适 | K22: 足量优质蛋白/规律作息/适度运动 | L22: 继续保持
A23: >25000 | B23: （高压力状态） | C23: 呈现平静无感或明显紧绷的两极状态，身心持续耗损，难以彻底放松 | F23: 必须矿物质 | G23: 骨骼舒适，肌力正常 | H23: 偶有酸痛，睡眠较浅 | I23: 腰膝酸软，易发抽筋 | J23: 周身酸胀，精力不足 | K23: 拉伸放松 / 矿物质补充 / 多维调理 | L23: 继续保持
F24: 芳香疗法 | G24: 气息调和，身心舒缓 | H24: 敏感易烦，静息不足 | I24: 心绪杂乱，睡眠不稳 | J24: 情绪郁结，身心紧绷 | K24: 芳香嗅吸/日常香薰/局部按摩 | L24: 继续保持
A25: 方案建议： | F25: 水溶性维生素 | G25: 含量充足，代谢顺畅 | H25: 微量缺乏，偶有不适 | I25: 明显不足，易上火疲劳 | J25: 严重缺失，黏膜反复不适 | K25: 新鲜果蔬/均衡饮食/每日补水 | L25: 继续保持
A26: 以轻量阶段式方案为主，营养补充和物理辅助调理结合，生活方式调整及运动。 | F26: 脂溶性维生素 | G26: 储备充足，吸收良好 | H26: 储备偏低，皮肤干涩 | I26: 吸收受阻，免疫力下滑 | J26: 重度匮乏，代谢机能减弱 | K26: 优质油脂/深色蔬果/适度日晒 | L26: 继续保持
F27: 一般消化系统 | G27: 消化顺畅，排便规律 | H27: 餐后偶胀，排便不稳 | I27: 时常反酸，肠胃敏感 | J27: 反复胃痛，排泄紊乱 | K27: 少食刺激/少食多餐/饭后散步 | L27: 继续保持
F28: 碳水化合物代谢 | G28: 供能平稳，血糖稳定 | H28: 餐后易困，血糖小幅波动 | I28: 糖分不耐，易发胖犯困 | J28: 胰岛素波动，疲劳频发 | K28: 控精制糖/粗细搭配/规律运动 | L28: 继续保持
F29: 蛋白质和脂类代谢 | G29: 合成分解平衡，体态稳定 | H29: 代谢缓慢，易水肿乏力 | I29: 代谢失调，血脂波动明显 | J29: 通路阻滞，体重异常波动 | K29: 优质蛋白/少油饮食/力量训练 | L29: 继续保持
F30: 外源性物质 | G30: 代谢清除顺畅无蓄积 | H30: 少量残留，晨起轻微疲惫 | I30: 毒素堆积，面色暗沉长痘 | J30: 大量蓄积，身体频繁不适 | K30: 多喝水/清淡饮食/减少加工食品 | L30: 继续保持
A31: 健康问题： | B31: 推荐产品： | F31: 外源性物质额外因素 | G31: 无额外毒素负担 | H31: 少量外界刺激影响代谢 | I31: 多重外源刺激加重负担 | J31: 多种毒素叠加损伤机体 | K31: 规避香精添加剂/减少环境刺激 | L31: 继续保持
A32: 肠胃不好 | B32: 综合消化酶 | F32: 导致健康风险和健康恶化的原因 | G32: 无多重负面诱因，身心自愈稳定 | H32: 少量诱因侵扰，轻微身心损耗 | I32: 多类诱因叠加，躯体持续不适 | J32: 各类负面因素堆积，健康持续下滑 | K32: 疏导压力/调理营养/规避毒素/修复创伤 | L32: 继续保持
A33: 肠道菌群 | B33: 益生菌 | F33: 情绪压力 | G33: 心态平和，抗压性强 | H33: 小事易烦躁，恢复较快 | I33: 持续烦闷，睡眠受影响 | J33: 长期压抑，身心持续耗损 | K33: 香薰放松/倾诉疏导/每日放空 | L33: 继续保持
B34: 维生素D3 | F34: 压力指数和压力来源 | G34: 压力值正常，无持续应激 | H34: 轻度应激，情绪短暂起伏 | I34: 压力偏高，躯体出现不适 | J34: 高压持续，多器官受影响 | K34: 梳理压力源/正念呼吸/休闲放松 | L34: 继续保持
B35: 复合维生素B族 | F35: 神经递质 | G35: 分泌均衡，情绪睡眠稳定 | H35: 分泌轻微失衡，专注力下降 | I35: 递质紊乱，多梦焦虑失眠 | J35: 递质严重失调，情绪失控易怒 | K35: 优质蛋白/B 族维生素/舒缓运动 | L35: 继续保持
A36: 睡眠不好 | B36: GABA氨基丁酸 | C36: 厉眠 | F36: 内分泌激素 | G36: 代谢平稳，情绪平和 | H36: 情绪波动，睡眠变差 | I36: 烦躁失眠，节律紊乱 | J36: 内分泌紊乱，状态不稳 | K36: 放松训练/营养素调节/内分泌咨询 | L36: 继续保持
A37: 代谢不好：甘油三酯，肥胖，胆固醇 | B37: 深海鱼油
A38: 脑功能下降，记忆力 | B38: 卵磷脂
A39: 矿物质 | B39: 多维、多矿
A40: 焦虑，情绪问题，压力大 | B40: 甘氨酸镁剂

Sheet 1.基本体质
B1: 身体基本体质评估报告
B2: 数据总结
B3: 本类别共检测 15 个项目。
B4: 分析建议:
B5: 本页项目反应值有对应的解释，请参考项目的数值说明。
B17: 检测项目 | C17: 反应值 | D17: 数值说明 | E17: 身体反应与症状 | F17: 小于50 | G17: 大于100 | H17: 正常值
B18: 电压（体力）指数 | C18: 81 | D18: 100到80：正常 80到50：偏弱 50以下：慢性压力 | E18: 指数低于80时，身体感觉疲劳、倦怠、乏力 | F18: =IF(C18<=50,C18,0) -> 0 | G18: =IF(50>C18>=80,C18,0) -> 81 | H18: =IF(AND(C18>80,C18<=100),C18,0) -> 81 | I18: Volt
B19: 电流强度（脑力）指数 | C19: 48 | D19: 100到80：正常 80到50：偏弱 50以下：慢性压力 | E19: 指数低于80时，反应脑部功能偏弱，思虑较多，记忆力下降，睡眠质量差。 | F19: =IF(C19<=50,C19,0) -> 48 | G19: =IF(50>C19>=80,C19,0) -> 48 | H19: =IF(AND(C19>80,C19<=100),C19,0) -> 0 | I19: Amper
B20: 电阻（免疫力）指数 | C20: 66 | D20: 100到80：正常 80到50：偏弱 50以下：慢性压力 | E20: 指数低于80时，表示身体免疫失衡，抵抗病毒、恶劣外在环境的能力偏弱。 | F20: =IF(C20<=50,C20,0) -> 0 | G20: =IF(50>C20>=80,C20,0) -> 66 | H20: =IF(AND(C20>80,C20<=100),C20,0) -> 0 | I20: Resistance
B21: 水合指数 | C21: 56 | D21: 100到80：正常 80到50：偏弱 50以下：慢性压力 | E21: 指数低于80时，表示身体细胞缺水，口渴及疲倦，皮肤干燥，易老化。 | F21: =IF(C21<=50,C21,0) -> 0 | G21: =IF(50>C21>=80,C21,0) -> 56 | H21: =IF(AND(C21>80,C21<=100),C21,0) -> 0 | I21: Hydration
B22: 氧化指数 | C22: 93 | D22: 100到80：正常 80到50：偏弱 50以下：慢性压力 | E22: 指数低于80时，表示血液携氧能力偏弱、缺乏运动、或贫血倾向等 | F22: =IF(C22<=50,C22,0) -> 0 | G22: =IF(50>C22>=80,C22,0) -> 93 | H22: =IF(AND(C22>80,C22<=100),C22,0) -> 93 | I22: Oxidation
B23: 质子压力指数 | C23: 71 | D23: 65以上正常 | E23: 与能量代谢相关。大脑的思考、身体的运动、生长、维持体温等所有生命活动，最终都依赖于由“质子压力”驱动的ATP生产。 | I23: Proton pressure
B24: 电子压力指数 | C24: 69 | D24: 电子压力与质子压力差正常不大于10 | E24: 能量转换，驱动ATP合成，细胞的能量来源 | I24: Electron pressure
B25: 共振频率指数 （压力指数） | C25: 24490 | D25: 1000以下退行性风险 15000以上神经体系压力 | E25: 指数大于15000时，表示神经过度活跃、压力、紧张、老化、过度情绪反应，或有身体疼痛。 低于1000时，表示身体疲劳，有退行性风险。 *注意：部分孩童、有高度精神意识、自闭症的人可能在更高的频率上振动，导致数值偏高，不要惊慌。 | I25: Major resonant frequency of the client
B26: 细胞反应指数 | C26: 5 | D26: 6以上正常 3以下慢性压力 | E26: 低于6时，细胞活力下降，与氧合、蛋白质消化、贫血、必需脂肪酸等营养摄入有关。 | I26: Reactance speed index
B27: 电抗速率指数 | C27: 6 | D27: 15以下理想， 40以下正常， 100以上疾病。 | E27: 电抗速率会受到许多日常因素的影响，如感染、全身性疲劳以及饮食中缺乏电解质等。 | I27: Phase angle
B28: 相反应指数 | C28: 560 | D28: 900+理想，700+正常， 500到700偏弱， 500到300关注， 300以下严密关注。 | E28: 相反应提示各系统、器官、神经的协同能力。300以下提示可能有重要问题。 | I28: Phase response react
B29: 阻抗指数 | C29: 1770 | D29: 1600+理想，1200+正常， 1000到1200弱， 800到1000关注， 800以下特别关注。 | E29: 800以下提示能量障碍阻止身体能量流通，提示可能有重要问题 | I29: Impedance
B30: 反映反应速度 | C30: 99 | D30: 数值＜19：反应状态正常； 数值＞19：轻度反应迟钝； 数值达到 40：中度反应迟钝； 数值达到 100：重度反应迟钝 | E30: 该数值越高，代表受测者当日身体反应灵敏度偏弱、反应迟缓 | I30: Parts per seconds for reaction speed
B31: 体脂率 | C31: 0.2 | D31: 根据性别： 13%-22%正常 高于26%关注 低于10%特别关注 | E31: 女性 男性 <15%：偏瘦 <12%：偏瘦 16%-22%：标准身材 13%-18%：标准身材 23%-28%：微胖 19%-25%：微胖 ＞29%：肥胖 ＞26%：肥胖 | I31: Body fat
B32: 相角指数 | C32: 7 | D32: 8以上理想，6以上正常， 3以下慢性压力。 | E32: 与人体细胞再生能力相关，是衡量细胞老化程度的指标。 低于 3 则表示健康状况差，有疾病风险。 | I32: Cellular vitality index (6 + normal, below 3 chronic):
B33: **报告说明：本报告用来评估目前身体健康的压力状态，不等同与医院和体检的检测结果，不用做诊断。

Sheet 2.氨基酸
B1: 氨基酸平衡性评估报告
B2: 数据总结
B3: 本类别共 29 个项目。
B4: 高反应项目(≥100): | D4: 3 | E4: 低反应项目(≤50): | F4: 2
B5: 分析建议:
B6: 反应值偏高可能表示相关系统存在压力或负担，建议关注。
B7: 反应值偏低可能表示相关营养素或功能不足，建议适当补充或调理。
B16: 反应值 | D16: 说明
B17: 50至100之间 | D17: 目前营养素在身体内为平衡状态
B18: 大于等于100 | D18: 提示该营养素目前或近期是不平衡状态。
B19: 小于等于50 | D19: 提示该营养素是长期不平衡状态。
B21: 检测项目 | D21: 反应值 | E21: 详解 | F21: 食物来源 | G21: 小于50 | H21: 大于100 | I21: 正常值
B22: 苯丙氨酸 | D22: 60 | E22: 疼痛控制，神经 | F22: 鸡蛋、牛奶、瘦肉、鱼类、大豆、坚果、奶酪 | G22: =IF(D22<=50,D22,0) -> 0 | H22: =IF(D22>=100,D22,0) -> 0 | I22: =IF(AND(D22>50,D22<100),D22,0) -> 60 | J22: Phenylalanine (pain control,nerves)
B23: 丙氨酸 | D23: 78 | E23: 肾脏和神经 | F23: 牛肉、鸡肉、鱼类、豆类、海藻、乳制品 | G23: =IF(D23<=50,D23,0) -> 0 | H23: =IF(D23>=100,D23,0) -> 0 | I23: =IF(AND(D23>50,D23<100),D23,0) -> 78 | J23: Alanine (kidney and nerves )
B24: 天冬酰胺 | D24: 88 | E24: 非必需氨基酸 | F24: 芦笋、豆类、土豆、牛肉、鱼类、坚果 | G24: =IF(D24<=50,D24,0) -> 0 | H24: =IF(D24>=100,D24,0) -> 0 | I24: =IF(AND(D24>50,D24<100),D24,0) -> 88 | J24: Asparagine (non-essential amino acid)
B25: 半胱氨酸 | D25: 93 | E25: 肾脏利用 | F25: 鸡蛋、肉类、鱼类、大蒜、洋葱、燕麦、小麦胚芽 | G25: =IF(D25<=50,D25,0) -> 0 | H25: =IF(D25>=100,D25,0) -> 0 | I25: =IF(AND(D25>50,D25<100),D25,0) -> 93 | J25: Cysteine (kidney utilization )
B26: 亮氨酸 | D26: 49 | E26: 情绪控制，情感 | F26: 牛肉、鸡胸肉、鱼、鸡蛋、牛奶、大豆、坚果、乳清蛋白 | G26: =IF(D26<=50,D26,0) -> 49 | H26: =IF(D26>=100,D26,0) -> 0 | I26: =IF(AND(D26>50,D26<100),D26,0) -> 0 | J26: Leucine (mood control, emotions)
B27: 异亮氨酸 | D27: 107 | E27: 情绪控制，神经 | F27: 瘦肉、鱼类、鸡蛋、奶制品、豆类、坚果、全谷物 | G27: =IF(D27<=50,D27,0) -> 0 | H27: =IF(D27>=100,D27,0) -> 107 | I27: =IF(AND(D27>50,D27<100),D27,0) -> 0 | J27: Isoleucine (emotional control, nerves)
B28: 丝氨酸 | D28: 57 | E28: 碳水化合物能量转化 | F28: 大豆、花生、鸡蛋、肉类、鱼类、乳制品 | G28: =IF(D28<=50,D28,0) -> 0 | H28: =IF(D28>=100,D28,0) -> 0 | I28: =IF(AND(D28>50,D28<100),D28,0) -> 57 | J28: Serine (carbohydrate energy conversion)
B29: 色氨酸 | D29: 72 | E29: 血清素和放松 | F29: 火鸡、鸡肉、牛奶、酸奶、香蕉、燕麦、坚果、豆制品 | G29: =IF(D29<=50,D29,0) -> 0 | H29: =IF(D29>=100,D29,0) -> 0 | I29: =IF(AND(D29>50,D29<100),D29,0) -> 72 | J29: Tryptophan (serotonin and relaxation)
B30: 组氨酸 | D30: 76 | E30: 抗炎、抗过敏 | F30: 牛肉、猪肉、鸡肉、鱼、鸡蛋、大豆、豆类、坚果 | G30: =IF(D30<=50,D30,0) -> 0 | H30: =IF(D30>=100,D30,0) -> 0 | I30: =IF(AND(D30>50,D30<100),D30,0) -> 76 | J30: Histidine, (anti-inflammation, anti-allergy)
B31: 蛋氨酸 | D31: 96 | E31: 肝脏和供氧 | F31: 鸡蛋、鱼类、瘦肉、芝麻、葵花籽、豆类、乳制品 | G31: =IF(D31<=50,D31,0) -> 0 | H31: =IF(D31>=100,D31,0) -> 0 | I31: =IF(AND(D31>50,D31<100),D31,0) -> 96 | J31: Methionine (liver and oxygenation)
B32: 赖氨酸 | D32: 64 | E32: 抗疱疹病变，神经 | F32: 鱼肉、鸡肉、牛肉、鸡蛋、豆类、豆制品、乳制品 | G32: =IF(D32<=50,D32,0) -> 0 | H32: =IF(D32>=100,D32,0) -> 0 | I32: =IF(AND(D32>50,D32<100),D32,0) -> 64 | J32: Lysine (anti herpes lesion, nerves)
B33: 苏氨酸 | D33: 83 | E33: 激素和能量产生 | F33: 瘦肉、鱼类、鸡蛋、奶制品、豆类、坚果、蘑菇 | G33: =IF(D33<=50,D33,0) -> 0 | H33: =IF(D33>=100,D33,0) -> 0 | I33: =IF(AND(D33>50,D33<100),D33,0) -> 83 | J33: Threonine (hormonal and energy production)
... B50: GABA | D50: 78 | E50: 思维控制 | F50: 发芽糙米、绿茶、番茄、土豆、南瓜、发酵食品 | G50: =IF(D50<=50,D50,0) -> 0 | H50: =IF(D50>=100,D50,0) -> 0 | I50: =IF(AND(D50>50,D50<100),D50,0) -> 78 | J50: Gaba (thought control)
B51: **报告说明：本报告用来评估目前身体健康的压力状态，不等同与医院和体检的检测结果，不用做诊断。

Sheet 3.矿物质
B1: 矿物质平衡性评估报告-重金属
B2: 数据总结
B3: 本类别共 6 个项目。
B4: 高反应项目(≥100): | D4: 3 | E4: 低反应项目(≤50): | F4: 2
B5: 分析建议:
B6: 反应值偏高可能表示相关系统存在压力或负担，建议关注。
B7: 反应值偏低可能表示相关营养素或功能不足，建议适当补充或调理。
B16: 反应值 | D16: 说明
B17: 50至100之间 | D17: 目前营养素在身体内为平衡状态
B18: 大于等于100 | D18: 提示该营养素目前或近期是不平衡状态。
B19: 小于等于50 | D19: 提示该营养素是长期不平衡状态。
B21: 检测项目 | D21: 反应值 | E21: 详解 | F21: 食物来源 | G21: 小于50 | H21: 大于100 | I21: 正常值
B22: 砷 | D22: 112 | E22: 能量、神经相关 | F22: 砷：海鲜、虾蟹、海带、谷类 | G22: =IF(D22<=50,D22,0) -> 0 | H22: =IF(D22>=100,D22,0) -> 112 | I22: =IF(AND(D22>50,D22<100),D22,0) -> 0 | J22: Arsenic (energy,nerves)
B23: 锑 | D23: 87 | E23: 皮肤、排毒、肠道功能相关 | F23: 锑：深海鱼、海带、肉类（微量） | G23: =IF(D23<=50,D23,0) -> 0 | H23: =IF(D23>=100,D23,0) -> 0 | I23: =IF(AND(D23>50,D23<100),D23,0) -> 87 | J23: Antimony (skin,detox,bowel function)
B24: 铝 | D24: 78 | E24: 神经、思维调节相关 | F24: 铝：茶叶、海带、土豆、加工食品 | G24: =IF(D24<=50,D24,0) -> 0 | H24: =IF(D24>=100,D24,0) -> 0 | I24: =IF(AND(D24>50,D24<100),D24,0) -> 78 | J24: Aluminum (nerves, thought regulation)
B25: 镍 | D25: 82 | E25: 肝功能、心肌相关 | F25: 镍：燕麦、坚果、豆类、巧克力 | G25: =IF(D25<=50,D25,0) -> 0 | H25: =IF(D25>=100,D25,0) -> 0 | I25: =IF(AND(D25>50,D25<100),D25,0) -> 82 | J25: Nickel (liver function, heart muscle)
B26: 金 | D26: 57 | E26: 排毒、思维调节相关 | F26: 金：海产品、菌类（微量） | G26: =IF(D26<=50,D26,0) -> 0 | H26: =IF(D26>=100,D26,0) -> 0 | I26: =IF(AND(D26>50,D26<100),D26,0) -> 57 | J26: Gold (detox, thought regulation)
B27: 银 | D27: 65 | E27: 免疫力、能量、排毒相关 | F27: 银：牛奶、鸡蛋、鱼类（微量） | G27: =IF(D27<=50,D27,0) -> 0 | H27: =IF(D27>=100,D27,0) -> 0 | I27: =IF(AND(D27>50,D27<100),D27,0) -> 65 | J27: Silver (immunity, energy, detox)
B28: **报告说明：本报告用来评估目前身体健康的压力状态，不等同与医院和体检的检测结果，不用做诊断。
B29: 矿物质平衡性评估报告-其他
B30: 数据总结
B31: 本类别共检测 23 个项目。 高反应项目(≥100): 2 个 | 低反应项目(≤50): 4 个
B32: 分析建议: 有 2 个项目反应值偏高(≥100)，可能表示相关系统存在压力或负担，建议关注。有 4 个项目反应值偏低(≤50)，可能表示相关营养素或功能不足，建议适当补充或调理。
B41: 反应值 | D41: 说明
B42: 50至100之间 | D42: 该物质在身体内为平衡状态
B43: 大于等于100： | D43: 该物质代谢近期有压力，需要立即关注，并调整生活方式，饮食结构。
B44: 小于等于50： | D44: 该物质代谢长期有压力，需要密切关注，如果已有症状需要进一步做医学检验。
B46: 检测项目 | D46: 反应值 | E46: 详解 | F46: 食物来源 | G46: 小于50 | H46: 大于100 | I46: 正常值
B47: 钙 | D47: 128 | E47: 骨骼脆弱、神经、肾上腺相关 | F47: 奶、豆制品、小鱼虾、深绿菜 | G47: =IF(D47<=50,D47,0) -> 0 | H47: =IF(D47>=100,D47,0) -> 128 | I47: =IF(AND(D47>50,D47<100),D47,0) -> 0 | J47: Calcium (weak bones,nerves,adrenals)
B48: 钾 | D48: 115 | E48: 疲劳、神经、能量、心脏相关 | F48: 香蕉、土豆、菠菜、豆类 | G48: =IF(D48<=50,D48,0) -> 0 | H48: =IF(D48>=100,D48,0) -> 115 | I48: =IF(AND(D48>50,D48<100),D48,0) -> 0 | J48: Potassium (fatigue,nerves,energy,heart)
B49: 钠 | D49: 73 | E49: 抑郁、神经、疲劳、消化相关 | F49: 盐、酱油、加工食品 | G49: =IF(D49<=50,D49,0) -> 0 | H49: =IF(D49>=100,D49,0) -> 0 | I49: =IF(AND(D49>50,D49<100),D49,0) -> 73 | J49: Sodium(depression,nerves,fatigue,digestion)
B50: 氯 | D50: 98 | E50: 酸碱平衡、胃酸紊乱、神经相关 | F50: 食盐、咸菜、海带 | G50: =IF(D50<=50,D50,0) -> 0 | H50: =IF(D50>=100,D50,0) -> 0 | I50: =IF(AND(D50>50,D50<100),D50,0) -> 98 | J50: Chlorine (acid alk balance,stomach acid dis,nerves)
B51: 镁 | D51: 118 | E51: 肾上腺调节、氧供能相关 | F51: 坚果、全谷、深绿菜、香蕉 | G51: =IF(D51<=50,D51,0) -> 0 | H51: =IF(D51>=100,D51,0) -> 118 | I51: =IF(AND(D51>50,D51<100),D51,0) -> 0 | J51: Magnesium (adrenal regulation, oxygen energy)
B52: 铁 | D52: 125 | E52: 贫血、疲劳、氧供相关 | F52: 红肉、动物肝、血、黑木耳 | G52: =IF(D52<=50,D52,0) -> 0 | H52: =IF(D52>=100,D52,0) -> 125 | I52: =IF(AND(D52>50,D52<100),D52,0) -> 0 | J52: lron (anemia,fatigue,oxygen)
B53: 硫 | D53: 68 | E53: 排毒、能量、情绪、注意力不集中相关 | F53: 蛋、奶、肉、豆、十字花科 | G53: =IF(D53<=50,D53,0) -> 0 | H53: =IF(D53>=100,D53,0) -> 0 | I53: =IF(AND(D53>50,D53<100),D53,0) -> 68 | J53: Sulphur (detox,energy,emotions,unfocused)
B54: 锰 | D54: 50 | E54: 神经与肌肉疾病相关 | F54: 全谷、坚果、茶叶、豆类 | G54: =IF(D54<=50,D54,0) -> 50 | H54: =IF(D54>=100,D54,0) -> 0 | I54: =IF(AND(D54>50,D54<100),D54,0) -> 0 | J54: Manganese (nerval and muscle disease
B55: 铬 | D55: 65 | E55: 血糖调节、肌肉相关 | F55: 粗粮、西兰花、蛋黄、菌菇 | G55: =IF(D55<=50,D55,0) -> 0 | H55: =IF(D55>=100,D55,0) -> 0 | I55: =IF(AND(D55>50,D55<100),D55,0) -> 65 | J55: Chromium (sugar regulation, muscle )
B56: 硒 | D56: 88 | E56: 排毒、神经、能量、皮肤相关 | F56: 海产品、动物内脏、蛋、大蒜 | G56: =IF(D56<=50,D56,0) -> 0 | H56: =IF(D56>=100,D56,0) -> 0 | I56: =IF(AND(D56>50,D56<100),D56,0) -> 88 | J56: Zinc (immunity,oxygen,metabolic disease)
B57: 锌 | D57: 92 | E57: 免疫力、氧供、代谢疾病相关 | F57: 牡蛎、羔羊肉、山核桃、小虾、青豆、豌豆、蛋黄、全麦谷物、燕麦、花生、杏仁。 | G57: =IF(D57<=50,D57,0) -> 0 | H57: =IF(D57>=100,D57,0) -> 0 | I57: =IF(AND(D57>50,D57<100),D57,0) -> 92 | J57: Selenium (detox,nerves,energy,skin)
B58: 碘 | D58: 47 | E58: 甲状腺功能、能量、代谢相关 | F58: 海带紫菜、碘盐、海鱼 | G58: =IF(D58<=50,D58,0) -> 47 | H58: =IF(D58>=100,D58,0) -> 0 | I58: =IF(AND(D58>50,D58<100),D58,0) -> 0 | J58: lodine (thyroid function,energy,metabolism)
...

Sheet 4.芳香疗法
B1: 芳香疗法反应性评估报告
B2: 数据总结
B3: 本类别共 26 个项目。
B4: 高反应项目(≥100): | D4: 3 | E4: 低反应项目(≤50): | F4: 2
B5: 分析建议:
B6: 反应值偏高可能表示相关系统存在压力或负担，建议关注。
B7: 反应值偏低可能表示相关营养素或功能不足，建议适当补充或调理。
B16: 反应值 | D16: 说明
B17: 50至100之间 | D17: 该物质在身体内为平衡状态
B18: 大于等于100 | D18: 该物质代谢近期有压力，需要立即关注，并调整生活方式，饮食结构。
B19: 小于等于50 | D19: 该物质代谢长期有压力，需要密切关注。
B21: 检测项目 | D21: 反应值 | E21: 详解 | G21: 小于50 | H21: 大于100 | I21: 正常值
B22: 香脂油 | D22: 78 | E22: 抗菌和祛痰 | G22: =IF(D22<=50,D22,0) -> 0 | H22: =IF(D22>=100,D22,0) -> 0 | I22: =IF(AND(D22>50,D22<100),D22,0) -> 78 | J22: Balsam oil antiseptic and expectorant
B23: 罗勒芳香油 | D23: 68 | E23: 有助于消化，抗痉挛 | G23: =IF(D23<=50,D23,0) -> 0 | H23: =IF(D23>=100,D23,0) -> 0 | I23: =IF(AND(D23>50,D23<100),D23,0) -> 68 | J23: Basil aroma oil aids digestion, antispasmodic
B24: 卡吉普特香精油 | D24: 90 | E24: 胃肠、肺部抗菌 | G24: =IF(D24<=50,D24,0) -> 0 | H24: =IF(D24>=100,D24,0) -> 0 | I24: =IF(AND(D24>50,D24<100),D24,0) -> 90 | J24: cajeput aroma oil gastrointestinal, pulmonary antimicrobia
B25: 葛缕子香精油 | D25: 91 | E25: 餐后可预防胀气，促进消化 | G25: =IF(D25<=50,D25,0) -> 0 | H25: =IF(D25>=100,D25,0) -> 0 | I25: =IF(AND(D25>50,D25<100),D25,0) -> 91 | J25: Caraway aroma oil after meals prevents flatulence, stims digestion
B26: 雪松香精油 | D26: 65 | E26: 用于皮肤刺激、皮炎、干燥皮肤和湿疹 | G26: =IF(D26<=50,D26,0) -> 0 | H26: =IF(D26>=100,D26,0) -> 0 | I26: =IF(AND(D26>50,D26<100),D26,0) -> 65 | J26: Cedar aroma oil skin irritations, dermatosis, dny skin eczema
B27: 肉桂香精油 | D27: 88 | E27: 抗菌除臭、缓解恶心、便秘 | G27: =IF(D27<=50,D27,0) -> 0 | H27: =IF(D27>=100,D27,0) -> 0 | I27: =IF(AND(D27>50,D27<100),D27,0) -> 88 | J27: Cinnamon aroma oil antiseptic deodorant, nausea, constipation
B28: 丁香精油 | D28: 82 | E28: 抗菌、牙痛、消化不良、催情剂 | G28: =IF(D28<=50,D28,0) -> 0 | H28: =IF(D28>=100,D28,0) -> 0 | I28: =IF(AND(D28>50,D28<100),D28,0) -> 82 | J28: Clove aroma oil, antiseptic, toothache,indigestion, aphrodisiac
B29: 香菜油 | D29: 79 | E29: 助消化，防止发酵、腹胀、促进血液循环 | G29: =IF(D29<=50,D29,0) -> 0 | H29: =IF(D29>=100,D29,0) -> 0 | I29: =IF(AND(D29>50,D29<100),D29,0) -> 79 | J29: Coriander, aids digestion, prevents fermentation, bloating, circulation
B30: 柏木香精油 | D30: 89 | E30: 收敛性，收缩血管、静脉、腿部和脚部 | G30: =IF(D30<=50,D30,0) -> 0 | H30: =IF(D30>=100,D30,0) -> 0 | I30: =IF(AND(D30>50,D30<100),D30,0) -> 89 | J30: Cypress aroma oil, astringent, contracts veins, vericose, legs feet
B31: 桉树精油 | D31: 88 | E31: 呼吸道抗菌剂，抗病毒 | G31: =IF(D31<=50,D31,0) -> 0 | H31: =IF(D31>=100,D31,0) -> 0 | I31: =IF(AND(D31>50,D31<100),D31,0) -> 88 | J31: Eucalyptus aroma oil, antiseptic forrespiratory tract, antiviral
B32: 天竺葵香精油 | D32: 61 | E32: 湿疹、痤疮、割伤、皮炎、驱虫 | G32: =IF(D32<=50,D32,0) -> 0 | H32: =IF(D32>=100,D32,0) -> 0 | I32: =IF(AND(D32>50,D32<100),D32,0) -> 61 | J32: Geranium aroma oil, eczema, acne, cuts, dermatosis, insect repellant
B33: 葡萄柚香精油 | D33: 65 | E33: 心脏滋补剂，油性皮肤，清洁消化道 | G33: =IF(D33<=50,D33,0) -> 0 | H33: =IF(D33>=100,D33,0) -> 0 | I33: =IF(AND(D33>50,D33<100),D33,0) -> 65 | J33: Grapefruit aroma oil, heart tonic, oily skin, deans digestive tract
... B47: 依兰芳香油 | D47: 96 | E47: 高血压，壮阳药 | G47: =IF(D47<=50,D47,0) -> 0 | H47: =IF(D47>=100,D47,0) -> 0 | I47: =IF(AND(D47>50,D47<100),D47,0) -> 96 | J47: Ylang ylang aroma oil,hypertension,aphrodisiac
B48: **报告说明：本报告用来评估目前身体健康的压力状态，不等同与医院和体检的检测结果，不用做诊断。

Sheet 5.脊柱反应性
B1: 脊柱系统反应性评估报告
B2: 数据总结
B3: 本类别共 25个项目。
B4: 重度压力项目: | D4: 1 | E4: 中度压力项目: | F4: 5 | G4: 轻度压力项目: | H4: 6 | I4: 正常项目: | J4: 13
B5: 分析建议:
B6: 压力项目可能表示相关位置脊柱有不同程度的压力，建议注意坐姿，增加锻炼，避免长时间的伏案工作。
B17: 压力状态 | E17: 反应项
B18: 重度压力 | E18: 神经压迫
B19: 中度压力 | E19: 暂时性神经压迫、退化、炎症
B20: 轻度压力 | E20: 未校正、困难、半脱位
B21: 正常压力 | E21: 已校正
B23: 脊柱名称 | E23: 压力状态 | F23: 对应身体的部位和区域
B24: C1 | C24: 颈椎 | E24: 神经压迫 | F24: 头部血液供应，脑垂体，头皮，脸部骨骼，大脑，内耳及中耳，交感神经系统。 | K24: Cervical | L24: Nervcompression
B25: C2 | C25: 颈椎 | E25: 未校正 | F25: 双耳，视神经，听觉神经，额窦，乳突，舌，前额。 | K25: Cervical | L25: Not corrected
B26: C3 | C26: 颈椎 | E26: 暂时性神经压迫 | F26: 脸颊，外耳，面部骨骼，牙，三叉神经。 | K26: Cervical | L26: Temp nerve comp
B27: C4 | C27: 颈椎 | E27: 退化 | F27: 鼻，唇，嘴，耳咽。 | K27: Cervical | L27: Degeneration
B28: C5 | C28: 颈椎 | E28: 已校正 | F28: 声带，腺体，咽。 | K28: Cervical | L28: Corrected
B29: C6 | C29: 颈椎 | E29: 未校正 | F29: 颈部肌肉，肩，扁桃体 | K29: Cervical | L29: Not corrected
B30: C7 | C30: 颈椎 | E30: 已校正 | F30: 甲状腺，肩关节，肘关节 | K30: Cervical | L30: Corrected
B31: T1 | C31: 胸锥 | E31: 已校正 | F31: 前臂，包括手、腕及手指，食管，气管。 | K31: Thoracic | L31: Corrected
B32: T2 | C32: 胸锥 | E32: 已校正 | F32: 心，包括瓣膜及心包，冠状动脉。 | K32: Thoracic | L32: Corrected
B33: T3 | C33: 胸锥 | E33: 已校正 | F33: 肺，支气管，胸膜，胸廓，乳房 | K33: Thoracic | L33: Corrected
B34: T4 | C34: 胸锥 | E34: 未校正 | F34: 胆囊，胆总管 | K34: Thoracic | L34: Not corrected
B35: T5 | C35: 胸锥 | E35: 已校正 | F35: 肝，腹腔神经丛，总循环系统。 | K35: Thoracic | L35: Corrected
... B48: 骶骨 | C48: 骶骨 | E48: 已校正 | F48: 股骨，臀部 | K48: Sacral | L48: Difficult
B49: **报告说明：本报告用来评估目前身体健康的压力状态，不等同与医院和体检的检测结果，不用做诊断。

Sheet 6.水溶性维生素
B1: 水溶性维生素平衡评估报告
B2: 数据总结
B3: 本类别共 27 个项目。
B4: 高反应项目(≥100): | D4: 3 | E4: 低反应项目(≤50): | F4: 2
B5: 分析建议:
B6: 反应值偏高可能表示相关系统存在压力或负担，建议关注。
B7: 反应值偏低可能表示相关营养素或功能不足，建议适当补充或调理。
B16: 反应值 | D16: 说明
B17: 50至100之间 | D17: 目前营养素在身体内为平衡状态
B18: 大于等于100 | D18: 提示该营养素目前或近期是不平衡状态。
B19: 小于等于50 | D19: 提示该营养素是长期不平衡状态。
B21: 检测项目 | D21: 反应值 | E21: 详解 | F21: 食物来源 | G21: 小于50 | H21: 大于100 | I21: 正常值
B22: B1-硫胺素 | D22: 81 | E22: 支持新陈代谢、神经功能、情绪和解毒 | F22: 糙米、豆类、牛奶、家禽。 | G22: =IF(D22<=50,D22,0) -> 0 | H22: =IF(D22>=100,D22,0) -> 0 | I22: =IF(AND(D22>50,D22<100),D22,0) -> 81 | J22: B1-thiamine: supports metabolism, nerve function, mood, and detoxification
B23: B2-核黄素 | D23: 75 | E23: 能量/碳水化合物代谢、神经系统、偏头痛、白内障 | F23: 动物肝脏、瘦肉、酵母、大豆、米糠及绿叶蔬菜。 | G23: =IF(D23<=50,D23,0) -> 0 | H23: =IF(D23>=100,D23,0) -> 0 | I23: =IF(AND(D23>50,D23<100),D23,0) -> 75 | J23: B2-riboflavin: energy/carbohydrate metabolism, nervous sys, migraines, cataracts
B24: B3-烟酸 | D24: 84 | E24: 酶功能、焦虑、ADHD、关节炎、糖尿病、失眠 | F24: 绿叶蔬菜，肾，肝，蛋等 | G24: =IF(D24<=50,D24,0) -> 0 | H24: =IF(D24>=100,D24,0) -> 0 | I24: =IF(AND(D24>50,D24<100),D24,0) -> 84 | J24: B3-niacin: enzymes, anxiety, add/adhd,schizophrenia, oa, ra, diabetes, insomnia
B25: 烟酰胺 | D25: 82 | E25: 体内脂肪和糖的功能，维持健康细胞 | F25: 肉、肝脏、鱼虾、花生、粗粮 | G25: =IF(D25<=50,D25,0) -> 0 | H25: =IF(D25>=100,D25,0) -> 0 | I25: =IF(AND(D25>50,D25<100),D25,0) -> 82 | J25: Niacinamide: function of fats and sugars in the body, maintaining healthy cells
B26: B5-泛酸 | D26: 86 | E26: 辅酶A生成、胆固醇、神经/认知功能、解毒 | F26: 糙米，肝，蛋，肉。 | G26: =IF(D26<=50,D26,0) -> 0 | H26: =IF(D26>=100,D26,0) -> 0 | I26: =IF(AND(D26>50,D26<100),D26,0) -> 86 | J26: B5-pantothenic acid: co.a production,cholesterol, neural/cognitive function, detox
B27: B6-吡哆醇 | D27: 108 | E27: 蛋白质/氨基酸代谢，免疫和神经系统健康 | F27: 瘦肉，果仁，糙米，绿叶蔬菜，香蕉。 | G27: =IF(D27<=50,D27,0) -> 0 | H27: =IF(D27>=100,D27,0) -> 108 | I27: =IF(AND(D27>50,D27<100),D27,0) -> 0 | J27: B6-pyridoxine: protein/aminoacid metabolism, immune and nervous system health
B28: B7-生物素 | D28: 72 | E28: 葡萄糖/脂肪酸代谢，免疫/神经系统 头发/指甲健康，念珠菌 | F28: 蔬菜，肉、酵母等 | G28: =IF(D28<=50,D28,0) -> 0 | H28: =IF(D28>=100,D28,0) -> 0 | I28: =IF(AND(D28>50,D28<100),D28,0) -> 72 | J28: B7-biotin: qlucose/fa metabolism,immune/nervous systems, hair/nail health candida
B29: 辅酶a | D29: 45 | E29: 碳水化合物/脂肪/蛋白质代谢过程，用于 能量产生 | F29: 动物肝脏、鸡蛋、瘦肉、蘑菇、粗粮、坚果 | G29: =IF(D29<=50,D29,0) -> 45 | H29: =IF(D29>=100,D29,0) -> 0 | I29: =IF(AND(D29>50,D29<100),D29,0) -> 0 | J29: Coenzyme a-coa: metabolic processes of carbs/fats/proteins for energy production
B30: B9叶酸 | D30: 74 | E30: 消化问题、贫血、能量、激素功能、情绪波动 | F30: 深绿色蔬菜、动物肝脏、豆类、坚果和全谷物 | G30: =IF(D30<=50,D30,0) -> 0 | H30: =IF(D30>=100,D30,0) -> 0 | I30: =IF(AND(D30>50,D30<100),D30,0) -> 74 | J30: B9 folic acid (digestive concern, anemia,energy, hormone function, moody)
B31: Paba | D31: 110 | E31: 白癜风、天疱疮、皮肌炎、头发/皮肤 rejuvenation，光毒性 | F31: 动物内脏、鸡蛋、全谷物、绿叶菜、酵母 | G31: =IF(D31<=50,D31,0) -> 0 | H31: =IF(D31>=100,D31,0) -> 110 | I31: =IF(AND(D31>50,D31<100),D31,0) -> 0 | J31: Paba: vitiligo, pemphigus, dermatomyositis,hair/skin rejuvenation, phototoxicity
B32: 肌醇 | D32: 79 | E32: 脂质、降胆固醇、抗高血压、促脂质代谢、 血管健康 | F32: 豆类、坚果、动物内脏、全谷物、柑橘 | G32: =IF(D32<=50,D32,0) -> 0 | H32: =IF(D32>=100,D32,0) -> 0 | I32: =IF(AND(D32>50,D32<100),D32,0) -> 79 | J32: Inositol: lipids, hypocholesterolemic,anti-hypertensive, lipotropic, vascular
B33: B12-甲钴胺 | D33: 56 | E33: 细胞分裂、血液形成、神经功能至关重要 | F33: 肝、肉、蛋、鱼、奶。 | G33: =IF(D33<=50,D33,0) -> 0 | H33: =IF(D33>=100,D33,0) -> 0 | I33: =IF(AND(D33>50,D33<100),D33,0) -> 56 | J33: B12-methylcobalamin: vital in cell division, blood formation, neuro function
... B48: 抗坏血酸 | D48: 95 | E48: 纯维生素C形式、强效抗氧化剂 | F48: 鲜枣、猕猴桃、柑橘、青椒、西兰花 | G48: =IF(D48<=50,D48,0) -> 0 | H48: =IF(D48>=100,D48,0) -> 0 | I48: =IF(AND(D48>50,D48<100),D48,0) -> 95 | J48: Ascorbic acid
B49: **报告说明：本报告用来评估目前身体健康的压力状态，不等同与医院和体检的检测结果，不用做诊断。

Sheet 7.脂溶性维生素
B1: 脂溶性维生素平衡评估报告
B2: 数据总结
B3: 本类别共 12 个项目。
B4: 高反应项目(≥100): | D4: 3 | E4: 低反应项目(≤50): | F4: 2
B5: 分析建议:
B6: 反应值偏高可能表示相关系统存在压力或负担，建议关注。
B7: 反应值偏低可能表示相关营养素或功能不足，建议适当补充或调理。
B16: 反应值 | D16: 说明
B17: 50至100之间 | D17: 目前营养素在身体内为平衡状态
B18: 大于等于100 | D18: 提示该营养素目前或近期是不平衡状态。
B19: 小于等于50 | D19: 提示该营养素是长期不平衡状态。
B21: 检测项目 | D21: 反应值 | E21: 详解 | F21: 食物来源 | G21: 小于50 | H21: 大于100 | I21: 正常值
B22: β-胡萝卜素 | D22: 52 | E22: 抗氧化，保护视力、皮肤与黏膜，增强免疫力 | F22: 橙黄色蔬果 + 深绿色蔬菜 | G22: =IF(D22<=50,D22,0) -> 0 | H22: =IF(D22>=100,D22,0) -> 0 | I22: =IF(AND(D22>50,D22<100),D22,0) -> 52 | J22: Beta carotene
B23: 鱼油 | D23: 66 | E23: 抗炎护心脑、保护视力、调节血脂、维护关节 | F23: 三文鱼、金枪鱼，秋刀鱼、沙丁鱼、鲭鱼 | G23: =IF(D23<=50,D23,0) -> 0 | H23: =IF(D23>=100,D23,0) -> 0 | I23: =IF(AND(D23>50,D23<100),D23,0) -> 66 | J23: Fish oil
B24: 视黄醇 | D24: 39 | E24: 保护视力、皮肤与黏膜、促生长发育与免疫功能 | F24: 肝、蛋黄、奶、深海鱼 | G24: =IF(D24<=50,D24,0) -> 39 | H24: =IF(D24>=100,D24,0) -> 0 | I24: =IF(AND(D24>50,D24<100),D24,0) -> 0 | J24: Retinol
B25: 维生素a前体 | D25: 71 | E25: 保护视力、上皮组织、增强免疫力、抗氧化 | F25: 胡萝卜、南瓜、红薯菠菜、西兰花、空心菜 | G25: =IF(D25<=50,D25,0) -> 0 | H25: =IF(D25>=100,D25,0) -> 0 | I25: =IF(AND(D25>50,D25<100),D25,0) -> 71 | J25: Vitamin a precursor
B26: 软骨维生素a | D26: 62 | E26: 维护关节软骨、黏膜与视力，骨骼生长、免疫修复 | F26: 肝、蛋黄、深海鱼、奶、黄绿蔬菜、软骨筋蹄 | G26: =IF(D26<=50,D26,0) -> 0 | H26: =IF(D26>=100,D26,0) -> 0 | I26: =IF(AND(D26>50,D26<100),D26,0) -> 62 | J26: Cartilage vit a
B27: 维生素D3 | D27: 93 | E27: 人体主要维生素D形式、骨骼健康 | F27: 海鱼、肝、蛋黄、全脂奶 | G27: =IF(D27<=50,D27,0) -> 0 | H27: =IF(D27>=100,D27,0) -> 0 | I27: =IF(AND(D27>50,D27<100),D27,0) -> 93 | J27: Vitamin d3
B28: 维生素E 1 | D28: 54 | E28: α-生育酚、主要抗氧化形式 | F28: 坚果、植物油、豆类、蛋黄、绿叶菜 | G28: =IF(D28<=50,D28,0) -> 0 | H28: =IF(D28>=100,D28,0) -> 0 | I28: =IF(AND(D28>50,D28<100),D28,0) -> 54 | J28: Vitamin e 1
B29: 维生素E 2 | D29: 49 | E29: β-生育酚、抗氧化作用 | F29: 大豆油、玉米油、坚果、粗粮、绿叶菜 | G29: =IF(D29<=50,D29,0) -> 49 | H29: =IF(D29>=100,D29,0) -> 0 | I29: =IF(AND(D29>50,D29<100),D29,0) -> 0 | J29: Vitamin e 2
B30: 维生素E 3 | D30: 98 | E30: γ-生育酚、抗炎、心血管保护 | F30: 大豆玉米油、坚果、豆类、粗粮 | G30: =IF(D30<=50,D30,0) -> 0 | H30: =IF(D30>=100,D30,0) -> 0 | I30: =IF(AND(D30>50,D30<100),D30,0) -> 98 | J30: Vitamin e 3
B31: 维生素 K1 | D31: 56 | E31: 凝血止血、强骨。 | F31: 深绿叶菜（菠菜、羽衣甘蓝）、西兰花 | G31: =IF(D31<=50,D31,0) -> 0 | H31: =IF(D31>=100,D31,0) -> 0 | I31: =IF(AND(D31>50,D31<100),D31,0) -> 56 | J31: Vitamin k 1
B32: 维生素 K2 | D32: 39 | E32: 引钙入骨、护血管、防钙化 | F32: 纳豆、发酵食品、动物肝脏、奶酪 | G32: =IF(D32<=50,D32,0) -> 39 | H32: =IF(D32>=100,D32,0) -> 0 | I32: =IF(AND(D32>50,D32<100),D32,0) -> 0 | J32: Vitamin k 2
B33: 辅酶Q10 | D33: 72 | E33: 主要辅酶Q形式、心脏能量 | F33: 沙丁鱼、牛肉、花生 | G33: =IF(D33<=50,D33,0) -> 0 | H33: =IF(D33>=100,D33,0) -> 0 | I33: =IF(AND(D33>50,D33<100),D33,0) -> 72 | J33: Co q 10
B34: **报告说明：本报告用来评估目前身体健康的压力状态，不等同与医院和体检的检测结果，不用做诊断。

Sheet 8.一般消化系统
B1: 一般消化系统评估报告
B2: 数据总结
B3: 本类别共 7 个项目。
B4: 高反应项目(≥100): | C4: 3 | D4: 低反应项目(≤50): | E4: 2
B5: 分析建议:
B6: 反应值偏高可能表示相关系统存在压力或负担，建议关注。
B7: 反应值偏低可能表示相关营养素或功能不足，建议适当补充或调理。
B15: 反应值 | C15: 说明
B16: 50至100之间 | C16: 该消化器官在身体内为平衡状态
B17: 大于等于100 | C17: 该消化器官近期有压力，或最近感觉不适，需要适当关注并调整生活方式，饮食结构
B18: 小于等于50 | C18: 该消化器官长期有压力，甚至形成疾病，需要密切关注如果已有症状需要进一步做医学检验
B20: 检测项目 | C20: 反应值 | D20: 详解 | G20: 小于50 | H20: 大于100 | I20: 正常值
B21: 口腔 | C21: 45 | D21: 消化起始、食物机械和化学分解 | G21: =IF(C21<=50,C21,0) -> 45 | H21: =IF(C21>=100,C21,0) -> 0 | I21: =IF(AND(C21>50,C21<100),C21,0) -> 0 | J21: Mouth
B22: 胃 | C22: 96 | D22: 蛋白质消化、胃酸分泌 | G22: =IF(C22<=50,C22,0) -> 0 | H22: =IF(C22>=100,C22,0) -> 0 | I22: =IF(AND(C22>50,C22<100),C22,0) -> 96 | J22: Stomach
B23: 十二指肠 | C23: 49 | D23: 小肠起始、胆汁和胰液作用 | G23: =IF(C23<=50,C23,0) -> 49 | H23: =IF(C23>=100,C23,0) -> 0 | I23: =IF(AND(C23>50,C23<100),C23,0) -> 0 | J23: Duodenum
B24: 空肠 | C24: 96 | D24: 营养吸收主要部位 | G24: =IF(C24<=50,C24,0) -> 0 | H24: =IF(C24>=100,C24,0) -> 0 | I24: =IF(AND(C24>50,C24<100),C24,0) -> 96 | J24: Jejunum
B25: 回肠 | C25: 102 | D25: 维生素B12和胆汁酸吸收 | G25: =IF(C25<=50,C25,0) -> 0 | H25: =IF(C25>=100,C25,0) -> 102 | I25: =IF(AND(C25>50,C25<100),C25,0) -> 0 | J25: lleum
B26: 结肠 | C26: 116 | D26: 水分吸收、肠道菌群发酵 | G26: =IF(C26<=50,C26,0) -> 0 | H26: =IF(C26>=100,C26,0) -> 116 | I26: =IF(AND(C26>50,C26<100),C26,0) -> 0 | J26: Colon
B27: 肠道菌群 | C27: 123 | D27: 益生菌平衡、免疫功能 | G27: =IF(C27<=50,C27,0) -> 0 | H27: =IF(C27>=100,C27,0) -> 123 | I27: =IF(AND(C27>50,C27<100),C27,0) -> 0 | J27: Bowel flora
B28: **报告说明：本报告用来评估目前身体健康的压力状态，不等同与医院和体检的检测结果，不用做诊断。

Sheet 9.碳水化合物代谢
B1: 碳水化合物代谢反应性评估报告
B2: 数据总结
B3: 本类别共 5 个项目。
B4: 高反应项目(≥100): | D4: 2 | E4: 低反应项目(≤50): | F4: 1
B5: 分析建议:
B6: 反应值偏高可能表示相关系统存在压力或负担，建议关注。
B7: 反应值偏低可能表示相关营养素或功能不足，建议适当补充或调理。
B16: 反应值 | D16: 说明
B17: 50至100之间 | D17: 该物质在身体内为平衡状态
B18: 大于等于100 | D18: 该物质代谢近期有压力，需要立即关注，并调整生活方式，饮食结构。
B19: 小于等于50 | D19: 该物质代谢长期有压力，需要密切关注，如果已有症状需要进一步做医学检验。
B21: 检测项目 | D21: 反应值 | E21: 详解 | H21: 小于50 | I21: 大于100 | J21: 正常值
B22: 果糖 | D22: 72 | E22: 水果中的糖吸收、肝脏代谢 | H22: =IF(D22<=50,D22,0) -> 0 | I22: =IF(D22>=100,D22,0) -> 0 | J22: =IF(AND(D22>50,D22<100),D22,0) -> 72 | K22: Fructose-levulose
B23: 麦芽糖 | D23: 44 | E23: 淀粉酶作用、复合碳水消化 | H23: =IF(D23<=50,D23,0) -> 44 | I23: =IF(D23>=100,D23,0) -> 0 | J23: =IF(AND(D23>50,D23<100),D23,0) -> 0 | K23: Maltose, starch
B24: 葡萄糖 | D24: 117 | E24: 主要单糖吸收、能量来源 | H24: =IF(D24<=50,D24,0) -> 0 | I24: =IF(D24>=100,D24,0) -> 117 | J24: =IF(AND(D24>50,D24<100),D24,0) -> 0 | K24: Glucose, galactose
B25: 乳糖 | D25: 97 | E25: 乳糖酶活性、乳制品消化 | H25: =IF(D25<=50,D25,0) -> 0 | I25: =IF(D25>=100,D25,0) -> 0 | J25: =IF(AND(D25>50,D25<100),D25,0) -> 97 | K25: Lactose type
B26: 蔗糖 | D26: 119 | E26: 蔗糖酶活性、糖代谢 | H26: =IF(D26<=50,D26,0) -> 0 | I26: =IF(D26>=100,D26,0) -> 119 | J26: =IF(AND(D26>50,D26<100),D26,0) -> 0 | K26: Sucrose, isomaltose type
B27: **报告说明：本报告用来评估目前身体健康的压力状态，不等同与医院和体检的检测结果，不用做诊断。

Sheet 10.蛋白质和脂类代谢
B1: 蛋白质和脂类代谢反应性评估报告
B2: 数据总结
B3: 本类别共 12 个项目。
B4: 高反应项目(≥100): | D4: 10 | E4: 低反应项目(≤50): | F4: 8
B5: 分析建议:
B6: 反应值偏高可能表示相关系统存在压力或负担，建议关注。
B7: 反应值偏低可能表示相关营养素或功能不足，建议适当补充或调理。
B16: 反应值 | D16: 说明
B17: 50至100之间 | D17: 该物质在身体内为平衡状态
B18: 大于等于100 | D18: 该物质代谢近期有压力，需要立即关注，并调整生活方式，饮食结构。
B19: 小于等于50 | D19: 该物质代谢长期有压力，需要密切关注，如果已有症状需要进一步做医学检验。
B21: 检测项目 | D21: 反应值 | E21: 详解 | H21: 小于50 | I21: 大于100 | J21: 正常值
B22: 甘油二酯，乙酰转移酶 | D22: 103 | E22: 脂肪合成、能量储存 | H22: =IF(D22<=50,D22,0) -> 0 | I22: =IF(D22>=100,D22,0) -> 103 | J22: =IF(AND(D22>50,D22<100),D22,0) -> 0 | K22: Diglyceride, acetyltransferase
B23: 磷脂 | D23: 52 | E23: 细胞膜结构、脂质信号 | H23: =IF(D23<=50,D23,0) -> 0 | I23: =IF(D23>=100,D23,0) -> 0 | J23: =IF(AND(D23>50,D23<100),D23,0) -> 52 | K23: Phospholipids
B24: 单甘油酯 | D24: 117 | E24: 脂肪消化中间产物 | H24: =IF(D24<=50,D24,0) -> 0 | I24: =IF(D24>=100,D24,0) -> 117 | J24: =IF(AND(D24>50,D24<100),D24,0) -> 0 | K24: Monoglyceride
B25: 胆固醇 | D25: 52 | E25: 细胞膜结构、激素合成 | H25: =IF(D25<=50,D25,0) -> 0 | I25: =IF(D25>=100,D25,0) -> 0 | J25: =IF(AND(D25>50,D25<100),D25,0) -> 52 | K25: Cholesterol
B26: 脂肪酸，co a连接酶 | D26: 117 | E26: 主要能量储存形式 | H26: =IF(D26<=50,D26,0) -> 0 | I26: =IF(D26>=100,D26,0) -> 117 | J26: =IF(AND(D26>50,D26<100),D26,0) -> 0 | K26: Fatty acid, co a ligase
B27: 甘油三酯 | D27: 50 | E27: 脂肪酸活化、β氧化 | H27: =IF(D27<=50,D27,0) -> 50 | I27: =IF(D27>=100,D27,0) -> 0 | J27: =IF(AND(D27>50,D27<100),D27,0) -> 0 | K27: Triglycerides
B28: 基础肽、胰蛋白酶、十二指肠 | D28: 117 | E28: 蛋白质初始消化、胰腺酶作用 | H28: =IF(D28<=50,D28,0) -> 0 | I28: =IF(D28>=100,D28,0) -> 117 | J28: =IF(AND(D28>50,D28<100),D28,0) -> 0 | K28: Basic peptides, trypsin, duodenum
B29: 芳香肽、糜蛋白酶、空肠 | D29: 82 | E29: 芳香族氨基酸消化 | H29: =IF(D29<=50,D29,0) -> 0 | I29: =IF(D29>=100,D29,0) -> 0 | J29: =IF(AND(D29>50,D29<100),D29,0) -> 82 | K29: Aromatic peptides, chymotrypsin, jejunum
B30: 脂肪族肽、弹性蛋白酶 | D30: 82 | E30: 弹性蛋白和结缔组织消化 | H30: =IF(D30<=50,D30,0) -> 0 | I30: =IF(D30>=100,D30,0) -> 0 | J30: =IF(AND(D30>50,D30<100),D30,0) -> 82 | K30: Aliphatic peptides, elastase
B31: Di-8-三肽 | D31: 49 | E31: 小肽吸收、寡肽转运 | H31: =IF(D31<=50,D31,0) -> 49 | I31: =IF(D31>=100,D31,0) -> 0 | J31: =IF(AND(D31>50,D31<100),D31,0) -> 0 | K31: Di-8-tri-peptides.
B32: 四肽，空肠 | D32: 70 | E32: 四肽消化、肠道吸收 | H32: =IF(D32<=50,D32,0) -> 0 | I32: =IF(D32>=100,D32,0) -> 0 | J32: =IF(AND(D32>50,D32<100),D32,0) -> 70 | K32: Tetra-peptides, jejunum
B33: 动物蛋白转化 | D33: 119 | E33: 动物蛋白消化效率 | H33: =IF(D33<=50,D33,0) -> 0 | I33: =IF(D33>=100,D33,0) -> 119 | J33: =IF(AND(D33>50,D33<100),D33,0) -> 0 | K33: Animal protein conversion
B34: **报告说明：本报告用来评估目前身体健康的压力状态，不等同与医院和体检的检测结果，不用做诊断。

Sheet 11.外源性物质
B1: 外源性物质反应性评估报告
B2: 数据总结
B3: 本类别共 12 个项目。
B4: 高反应项目(≥100): | D4: 0 | E4: 低反应项目(≤50): | F4: 0
B5: 分析建议:
B6: 反应值偏高可能表示相关系统存在压力或负担，建议关注。
B7: 反应值偏低可能表示相关营养素或功能不足，建议适当补充或调理。
B16: 反应值 | D16: 说明
B17: 50至100之间 | D17: 该物质在身体内为平衡状态
B18: 大于等于100 | D18: 该物质代谢近期有压力，需要立即关注，并调整生活方式，饮食结构。
B19: 小于等于50 | D19: 该物质代谢长期有压力，需要密切关注，如果已有症状需要进一步做医学检验。
B21: 检测项目 | D21: 反应值 | E21: 详解 | G21: 小于50 | H21: 大于100 | I21: 正常值
B22: 工业污染物 | D22: 86 | E22: 工业化学品暴露、解毒负担 | G22: =IF(D22<=50,D22,0) -> 0 | H22: =IF(D22>=100,D22,0) -> 0 | I22: =IF(AND(D22>50,D22<100),D22,0) -> 86 | J22: Industrial pollutant
B23: 辐射 | D23: 86 | E23: 电磁辐射、电离辐射影响 | G23: =IF(D23<=50,D23,0) -> 0 | H23: =IF(D23>=100,D23,0) -> 0 | I23: =IF(AND(D23>50,D23<100),D23,0) -> 86 | J23: Radiation
B24: 汞合金/牙科 | D24: 81 | E24: 汞暴露、口腔健康影响 | G24: =IF(D24<=50,D24,0) -> 0 | H24: =IF(D24>=100,D24,0) -> 0 | I24: =IF(AND(D24>50,D24<100),D24,0) -> 81 | J24: Amalgam/dental
B25: 环境因素 | D25: 81 | E25: 环境毒素整体暴露 | G25: =IF(D25<=50,D25,0) -> 0 | H25: =IF(D25>=100,D25,0) -> 0 | I25: =IF(AND(D25>50,D25<100),D25,0) -> 81 | J25: Environmental
B26: 美容店毒素 | D26: 79 | E26: 化妆品和个人护理品化学物质 | G26: =IF(D26<=50,D26,0) -> 0 | H26: =IF(D26>=100,D26,0) -> 0 | I26: =IF(AND(D26>50,D26<100),D26,0) -> 79 | J26: Cosmetic ingredients
B27: 重金属 | D27: 79 | E27: 铅、镉、砷等重金属暴露 | G27: =IF(D27<=50,D27,0) -> 0 | H27: =IF(D27>=100,D27,0) -> 0 | I27: =IF(AND(D27>50,D27<100),D27,0) -> 79 | J27: Heavy metals
B28: 食品添加剂 | D28: 77 | E28: 防腐剂、色素、调味剂 | G28: =IF(D28<=50,D28,0) -> 0 | H28: =IF(D28>=100,D28,0) -> 0 | I28: =IF(AND(D28>50,D28<100),D28,0) -> 77 | J28: Food additives
B29: 石棉 | D29: 76 | E29: 石棉纤维暴露、肺部健康 | G29: =IF(D29<=50,D29,0) -> 0 | H29: =IF(D29>=100,D29,0) -> 0 | I29: =IF(AND(D29>50,D29<100),D29,0) -> 76 | J29: Asbestos
B30: 药物 | D30: 74 | E30: 药物代谢、药物残留 | G30: =IF(D30<=50,D30,0) -> 0 | H30: =IF(D30>=100,D30,0) -> 0 | I30: =IF(AND(D30>50,D30<100),D30,0) -> 74 | J30: Pharmaceuticals
B31: 代谢/遗传 | D31: 73 | E31: 遗传代谢差异、解毒能力 | G31: =IF(D31<=50,D31,0) -> 0 | H31: =IF(D31>=100,D31,0) -> 0 | I31: =IF(AND(D31>50,D31<100),D31,0) -> 73 | J31: Metabolic c./heredity
B32: 杀虫剂 | D32: 61 | E32: 农药暴露、神经系统影响 | G32: =IF(D32<=50,D32,0) -> 0 | H32: =IF(D32>=100,D32,0) -> 0 | I32: =IF(AND(D32>50,D32<100),D32,0) -> 61 | J32: Insecticides
B33: 卤素-氯 | D33: 56 | E33: 氯化物、氯相关化合物 | G33: =IF(D33<=50,D33,0) -> 0 | H33: =IF(D33>=100,D33,0) -> 0 | I33: =IF(AND(D33>50,D33<100),D33,0) -> 56 | J33: Halogens-chlorine
B34: **报告说明：本报告用来评估目前身体健康的压力状态，不等同与医院和体检的检测结果，不用做诊断。

Sheet 12.外源性物质额外因素
B1: 外源性物质额外因素评估报告
B2: 数据总结
B3: 本类别共 15 个项目。
B4: 高反应项目(≥100): | D4: 8 | E4: 低反应项目(≤50): | F4: 2
B5: 分析建议:
B6: 反应值偏高可能表示相关系统存在压力或负担，建议关注。
B7: 反应值偏低可能表示相关营养素或功能不足，建议适当补充或调理。
B16: 反应值 | D16: 说明
B17: 50至100之间 | D17: 该物质在身体内为平衡状态
B18: 大于等于100： | D18: 该物质代谢近期有压力，需要立即关注，并调整生活方式，饮食结构。
B19: 小于等于50： | D19: 该物质代谢长期有压力，需要密切关注，如果已有症状需要进一步做医学检验。
B21: 检测项目 | D21: 反应值 | E21: 详解 | G21: 小于50 | H21: 大于100 | I21: 正常值
B22: 胃部损伤 | D22: 138 | E22: 胃黏膜损伤、溃疡风险 | G22: =IF(D22<=50,D22,0) -> 0 | H22: =IF(D22>=100,D22,0) -> 138 | I22: =IF(AND(D22>50,D22<100),D22,0) -> 0 | J22: Stomach violation
B23: 毒素的脑部滞留 | D23: 109 | E23: 猪肉相关毒素负担 | G23: =IF(D23<=50,D23,0) -> 0 | H23: =IF(D23>=100,D23,0) -> 109 | I23: =IF(AND(D23>50,D23<100),D23,0) -> 0 | J23: Mental retention of toxins
B24: 猪肉毒素 | D24: 55 | E24: 气候变化、温度波动影响 | G24: =IF(D24<=50,D24,0) -> 0 | H24: =IF(D24>=100,D24,0) -> 0 | I24: =IF(AND(D24>50,D24<100),D24,0) -> 55 | J24: Pork toxins
B25: 天气暴露 | D25: 70 | E25: 乳制品不耐受、毒素积累 | G25: =IF(D25<=50,D25,0) -> 0 | H25: =IF(D25>=100,D25,0) -> 0 | I25: =IF(AND(D25>50,D25<100),D25,0) -> 70 | J25: Weather exposure
B26: 乳制品毒素 | D26: 62 | E26: 慢性压力、皮质醇影响 | G26: =IF(D26<=50,D26,0) -> 0 | H26: =IF(D26>=100,D26,0) -> 0 | I26: =IF(AND(D26>50,D26<100),D26,0) -> 62 | J26: Dairy toxins
B27: 压力 | D27: 128 | E27: 肠道通透性增加、免疫反应 | G27: =IF(D27<=50,D27,0) -> 0 | H27: =IF(D27>=100,D27,0) -> 128 | I27: =IF(AND(D27>50,D27<100),D27,0) -> 0 | J27: Stress
B28: 肠漏综合征 | D28: 92 | E28: 药物依赖、神经化学影响 | G28: =IF(D28<=50,D28,0) -> 0 | H28: =IF(D28>=100,D28,0) -> 0 | I28: =IF(AND(D28>50,D28<100),D28,0) -> 92 | J28: Leaky gut syndrome
B29: 精神药物/成瘾 | D29: 96 | E29: 酒精代谢、肝脏负担 | G29: =IF(D29<=50,D29,0) -> 0 | H29: =IF(D29>=100,D29,0) -> 0 | I29: =IF(AND(D29>50,D29<100),D29,0) -> 96 | J29: St. drugs/addiction
B30: 酒精或乙醛 | D30: 93 | E30: 术后恢复、组织修复需求 | G30: =IF(D30<=50,D30,0) -> 0 | H30: =IF(D30>=100,D30,0) -> 0 | I30: =IF(AND(D30>50,D30<100),D30,0) -> 93 | J30: Alcohol or aldehyde
B31: 手术/组织创伤 | D31: 95 | E31: 创伤后应激、身体恢复 | G31: =IF(D31<=50,D31,0) -> 0 | H31: =IF(D31>=100,D31,0) -> 0 | I31: =IF(AND(D31>50,D31<100),D31,0) -> 95 | J31: Surgery/tissue trauma
B32: 受伤/事故 | D32: 143 | E32: 咖啡因敏感性、神经系统 | G32: =IF(D32<=50,D32,0) -> 0 | H32: =IF(D32>=100,D32,0) -> 143 | I32: =IF(AND(D32>50,D32<100),D32,0) -> 0 | J32: Injury/accident
B33: 咖啡因/兴奋剂 | D33: 69 | E33: 吸烟影响、血管健康 | G33: =IF(D33<=50,D33,0) -> 0 | H33: =IF(D33>=100,D33,0) -> 0 | I33: =IF(AND(D33>50,D33<100),D33,0) -> 69 | J33: Caffeine/stimulants
... B36: 便秘 | D36: 38 | E36: 肠道蠕动、排毒功能 | G36: =IF(D36<=50,D36,0) -> 38 | H36: =IF(D36>=100,D36,0) -> 0 | I36: =IF(AND(D36>50,D36<100),D36,0) -> 0 | J36: Constipation
B37: **报告说明：本报告用来评估目前身体健康的压力状态，不等同与医院和体检的检测结果，不用做诊断。

Sheet 13.导致健康风险和健康恶化的原因
B1: 导致健康风险的原因评估报告
B2: 数据总结
B3: 本类别共 20 个项目。
B4: 高反应项目(≥100): | D4: 6
B5: 分析建议:
B6: 反应值偏高可能表示相关系统存在压力或负担，建议关注。
B15: 反应值 | D15: 说明
B16: 50至100之间
B17: 大于等于100：
B19: 检测项目 | D19: 反应值 | E19: 详解 | F19: 小于50 | G19: 大于100 | H19: 正常值
B20: 心理因素 | D20: 118 | E20: 情绪和心理状态对疾病的影响 | F20: =IF(D20<=50,D20,0) -> 0 | G20: =IF(D20>=100,D20,0) -> 118 | H20: =IF(AND(D20>50,D20<100),D20,0) -> 0 | I20: Mental Factors
B21: 缺乏意识 | D21: 111 | E21: 对自身健康状况认知不足 | F21: =IF(D21<=50,D21,0) -> 0 | G21: =IF(D21>=100,D21,0) -> 111 | H21: =IF(AND(D21>50,D21<100),D21,0) -> 0 | I21: Lack of Awareness
B22: 欲望压力 | D22: 110 | E22: 欲望和期望造成的心理负担 | F22: =IF(D22<=50,D22,0) -> 0 | G22: =IF(D22>=100,D22,0) -> 110 | H22: =IF(AND(D22>50,D22<100),D22,0) -> 0 | I22: Desire Stress
B23: 病原体 | D23: 109 | E23: 细菌、病毒、真菌等感染因素 | F23: =IF(D23<=50,D23,0) -> 0 | G23: =IF(D23>=100,D23,0) -> 109 | H23: =IF(AND(D23>50,D23<100),D23,0) -> 0 | I23: Pathogens
B24: 创伤 | D24: 105 | E24: 身体或心理创伤的影响 | F24: =IF(D24<=50,D24,0) -> 0 | G24: =IF(D24>=100,D24,0) -> 105 | H24: =IF(AND(D24>50,D24<100),D24,0) -> 0 | I24: Trauma
B25: 人际关系压力 | D25: 100 | E25: 社交关系带来的压力 | F25: =IF(D25<=50,D25,0) -> 0 | G25: =IF(D25>=100,D25,0) -> 100 | H25: =IF(AND(D25>50,D25<100),D25,0) -> 0 | I25: Interpersonal Stress
B26: 毒性 | D26: 100 | E26: 体内毒素积累的影响 | F26: =IF(D26<=50,D26,0) -> 0 | G26: =IF(D26>=100,D26,0) -> 100 | H26: =IF(AND(D26>50,D26<100),D26,0) -> 0 | I26: Toxicity
B27: 过敏或敏感 | D27: 98 | E27: 过敏反应对健康的影响 | F27: =IF(D27<=50,D27,0) -> 0 | G27: =IF(D27>=100,D27,0) -> 0 | H27: =IF(AND(D27>50,D27<100),D27,0) -> 98 | I27: Allergy or Sensitivity
B28: 家庭压力 | D28: 88 | E28: 家庭环境和关系压力 | F28: =IF(D28<=50,D28,0) -> 0 | G28: =IF(D28>=100,D28,0) -> 0 | H28: =IF(AND(D28>50,D28<100),D28,0) -> 88 | I28: Family Stress
B29: 压力 | D29: 78 | E29: 一般性压力反应 | F29: =IF(D29<=50,D29,0) -> 0 | G29: =IF(D29>=100,D29,0) -> 0 | H29: =IF(AND(D29>50,D29<100),D29,0) -> 78 | I29: Stress
B30: 工作或学业压力 | D30: 72 | E30: 职业或学习相关压力 | F30: =IF(D30<=50,D30,0) -> 0 | G30: =IF(D30>=100,D30,0) -> 0 | H30: =IF(AND(D30>50,D30<100),D30,0) -> 72 | I30: Job or School Stress
B31: 对抗疗法/医源性 | D31: 70 | E31: 医疗治疗副作用 | F31: =IF(D31<=50,D31,0) -> 0 | G31: =IF(D31>=100,D31,0) -> 0 | H31: =IF(AND(D31>50,D31<100),D31,0) -> 70 | I31: Allopathy/Iatrogenic
... B39: 过度思考 | D39: 47 | E39: 过度分析和担忧 | F39: =IF(D39<=50,D39,0) -> 47 | G39: =IF(D39>=100,D39,0) -> 0 | H39: =IF(AND(D39>50,D39<100),D39,0) -> 0 | I39: Overthinking
B40: **报告说明：本报告用来评估目前身体健康的压力状态，不等同与医院和体检的检测结果，不用做诊断。
B41: 导致健康恶化的原因评估报告
B42: 数据总结
B43: 本类别共 20 个项目。
B44: 高反应项目(≥100): | D44: 6
B45: 分析建议:
B46: 反应值偏高可能表示相关系统存在压力或负担，建议关注。
B56: 反应值 | D56: 说明
B57: 50至100之间
B58: 大于等于100：
B60: 检测项目 | D60: 反应值 | E60: 详解 | F60: 小于50 | G60: 大于100 | H60: 正常值
B61: 欲望压力 | D61: 136 | E61: 欲望和期望加重症状 | F61: =IF(D61<=50,D61,0) -> 0 | G61: =IF(D61>=100,D61,0) -> 136 | H61: =IF(AND(D61>50,D61<100),D61,0) -> 0 | I61: Desire Stress
B62: 心理因素 | D62: 121 | E62: 心理状态恶化病情 | F62: =IF(D62<=50,D62,0) -> 0 | G62: =IF(D62>=100,D62,0) -> 121 | H62: =IF(AND(D62>50,D62<100),D62,0) -> 0 | I62: Mental Factors
B63: 人际压力 | D63: 116 | E63: 人际关系问题加重病情 | F63: =IF(D63<=50,D63,0) -> 0 | G63: =IF(D63>=100,D63,0) -> 116 | H63: =IF(AND(D63>50,D63<100),D63,0) -> 0 | I63: Interpersonal Stress
B64: 过敏或敏感 | D64: 102 | E64: 过敏反应加重症状 | F64: =IF(D64<=50,D64,0) -> 0 | G64: =IF(D64>=100,D64,0) -> 102 | H64: =IF(AND(D64>50,D64<100),D64,0) -> 0 | I64: Allergy or Sensitivity
B65: 缺乏意识 | D65: 91 | E65: 缺乏自我认知导致恶化 | F65: =IF(D65<=50,D65,0) -> 0 | G65: =IF(D65>=100,D65,0) -> 0 | H65: =IF(AND(D65>50,D65<100),D65,0) -> 91 | I65: Lack of Awareness
B66: 挣扎压力 | D66: 89 | E66: 内心挣扎加重病情 | F66: =IF(D66<=50,D66,0) -> 0 | G66: =IF(D66>=100,D66,0) -> 0 | H66: =IF(AND(D66>50,D66<100),D66,0) -> 89 | I66: Struggle with Self
...

Sheet 14.74项情绪
B1: 74项数字化多元情绪压力评估报告
B2: 数据总结
B3: 本类别共 74 个项目。
B4: 高反应项目(≥100): | D4: 2 | F4: 低反应项目(≤50): | G4: 5
B5: 分析建议:
B6: 反应值偏高可能表示相关情绪近期存在压力或负担，建议关注。
B7: 反应值偏低可能表示该情绪长期被隐藏，建议进行疏解或调理。
B9: 反应值最低的10项
B10: 数值低于50：代表内敛、隐藏的、没有解决或释放的失衡情绪
B11: 检测项目 | D11: 反应值 | F11: 检测项目 | H11: 反应值
B12: 欲望 | D12: 53 | F12: 欢笑 | H12: 49 | J12: Lust | K12: Laughter
B13: 困惑 | D13: 51 | F13: 震惊 | H13: 49 | J13: Confusion | K13: Shock
B14: 否认 | D14: 50 | F14: 被遗弃感 | H14: 44 | J14: Denial | K14: Abandonment
B15: 勇气 | D15: 50 | F15: 冷漠 | H15: 44 | J15: Courage | K15: Apathy
B16: 无法控制的躁狂 | D16: 50 | F16: 超感知觉 | H16: 42 | J16: Uncontrollable Manic | K16: ESP
B18: 解释说明
B19: 欲望 | D19: =_xlfn.IFNA(VLOOKUP(B19,情绪解释!$A$1:$B$74,2,0),"") -> 内心对事物、目标、满足感产生主动渴求与向往的内在驱动力，推动个体主动追求、行动与索取。 | J19: Lust
B20: 困惑 | D20: =_xlfn.IFNA(VLOOKUP(B20,情绪解释!$A$1:$B$74,2,0),"") -> 认知冲突信号，适度可促学习思考，过度难解则易引发焦虑、挫败与放弃。 | J20: Confusion
B21: 否认 | D21: =_xlfn.IFNA(VLOOKUP(B21,情绪解释!$A$1:$B$74,2,0),"") -> 为避免焦虑、守护心理平衡，无意识拒绝承认痛苦现实，是基础的自我保护防御机制。 | J21: Denial
B22: 勇气 | D22: =_xlfn.IFNA(VLOOKUP(B22,情绪解释!$A$1:$B$74,2,0),"") -> 涉及多心理要素互动的过程，核心是心怀恐惧仍为有价值的目标行动，不被恐惧统治。 | J22: Courage
B23: 无法控制的躁狂 | D23: =_xlfn.IFNA(VLOOKUP(B23,情绪解释!$A$1:$B$74,2,0),"") -> 状态异常高涨欣快，极易暴躁易怒，情绪起伏剧烈，判断力减弱，易冲动行事、不计后果。 | J23: Uncontrollable Manic
B24: 欢笑 | D24: =_xlfn.IFNA(VLOOKUP(B24,情绪解释!$A$1:$B$74,2,0),"") -> 积极情绪的表达，它通常是愉悦、快乐、喜悦和觉得有趣的非语言行为标志。 | J24: Laughter
B25: 震惊 | D25: =_xlfn.IFNA(VLOOKUP(B25,情绪解释!$A$1:$B$74,2,0),"") -> 遭遇极度意外、冲击力极强的重大事件时，产生的强烈、剧烈、失控的高强度情绪反应。 | J25: Shock
B26: 被遗弃感 | D26: =_xlfn.IFNA(VLOOKUP(B26,情绪解释!$A$1:$B$74,2,0),"") -> 核心是孤立无依的断裂感，源于恐惧被弃，情感忽视冷漠也会强烈引发。 | J26: Abandonment
B27: 冷漠 | D27: =_xlfn.IFNA(VLOOKUP(B27,情绪解释!$A$1:$B$74,2,0),"") -> 对人、事缺乏关心、热情与共情，表现为冷淡疏离、无动于衷，常带有情感隔离与漠视。 | J27: Apathy
B28: 超感知觉 | D28: =_xlfn.IFNA(VLOOKUP(B28,情绪解释!$A$1:$B$74,2,0),"") -> 指不通过已知感觉器官（视觉、听觉、触觉等）来接收外界信息的能力。俗称“第六感”。 | J28: ESP
B29: 74项情绪特征反应值
B30: 反应值最高的10项
B31: 数值高于100：代表外显型或近期失衡的情绪
B32: 检测项目 | D32: 反应值 | F32: 检测项目 | H32: 反应值
B33: 渴望改变现状 | D33: 120 | F33: 背叛 | H33: 94 | J33: Desire for Things to be Different | K33: Betrayal
B34: 敬畏感 | D34: 102 | F34: 不足感 | H34: 94 | J34: Awe | K34: Inadequacy
B35: 绝望 | D35: 102 | F35: 犹豫 | H35: 83 | J35: Hopeless Despair | K35: Hesitation
B36: 被误解 | D36: 96 | F36: 单调性 | H36: 82 | J36: Misunderstood | K36: Monotony
B37: 自我怀疑 | D37: 94 | F37: 坚定忠诚 | H37: 82 | J37: Self Doubt | K37: Steadfast Loyalty
B39: 解释说明
B40: 渴望改变现状 | D40: =_xlfn.IFNA(VLOOKUP(B40,情绪解释!$A$1:$B$74,2,0),"") -> 源于现实与期望的内心冲突，是对现状的不接纳，常含悔恨、无奈与焦虑，易造成持续痛苦。 | J40: Desire for Things to be Different
B41: 敬畏感 | D41: =_xlfn.IFNA(VLOOKUP(B41,情绪解释!$A$1:$B$74,2,0),"") -> 面对宏大事物时的复杂情感，超越认知框架，常引发深刻的认知转变与内心触动。 | J41: Awe
B42: 绝望 | D42: =_xlfn.IFNA(VLOOKUP(B42,情绪解释!$A$1:$B$74,2,0),"") -> 认知上的无力信念与情感上的痛苦空虚感，严重削弱动力与求生意志，需及时寻求专业帮助。 | J42: Hopeless Despair
B43: 被误解 | D43: =_xlfn.IFNA(VLOOKUP(B43,情绪解释!$A$1:$B$74,2,0),"") -> 内心想法与情感未被他人理解认可时产生的负面情绪，也是提醒我们修复人际连接的信号。 | J43: Misunderstood
...

Sheet 情绪解释
A1: 抗拒变化 | B1: 面对改变时，因视其为威胁而维持现状、拖延破坏，触发防御的行为情绪反应。
A2: 骄傲 | B2: 源于成就评估的自我意识情绪，分努力的健康真实型与以天赋自居的不良傲慢型。
A3: 宗教冲突 | B3: 不仅是外在宗教间的矛盾，更常是个人信仰与欲望、理性等的内部矛盾，会引发情绪困扰。
A4: 支配欲 | B4: 渴望掌控局面、他人或情境，愿占主导、按己意行事的心理倾向，伴复杂情绪动机。
A5: 嫉妒 | B5: 因他人拥有自己渴望的事物（如关系、优势）产生的羡慕与不满交织的复杂情绪。
A6: 担忧 | B6: 对未来可能发生的不利情况反复思虑、感到不安与紧张的情绪。
A7: 评判倾向 | B7: 评判主义是苛刻评判他人、忽视优点的心理；健康辨明是基于现实与价值观做判断，不贬低他人。
A8: 贪婪 | B8: 对财物、利益或满足感过度渴求，不知满足，总想占有更多的持续心理倾向。
A9: 恐惧 | B9: 原始的核心基本情绪，是应对危险的防御警报，伴随紧张不安与战或逃的生理反应。
A10: 内疚感 | B10: 因违背准则、伤害他人或未尽责任而产生的自省消极情绪，长期沉溺易引发抑郁焦虑。
A11: 合理化 | B11: 是一种非常重要的心理防御机制。个体无意识的做合理、逻辑化、社会可接受的安排。
A12: 感官享受 | B12: 以感官专注当下、感受非性化纯粹愉悦，通过身体体验世界、获得联结与满足的心理倾向。
... A74: 紧张感 | B74: 源于对未知未来的担忧，无明确即时刺激，和针对当下具体事物的恐惧存在明显区分。

Sheet 15.压力指数和来源
B1: 压力指数和压力来源评估报告
B2: 数据总结
B3: 本类别共12个项目。
B4: 高反应项目(≥100): | D4: 6
B5: 分析建议:
B6: 反应值偏高可能表示相关系统存在压力或负担，建议关注。
B15: 检测项目 | D15: 反应值 | E15: 数值说明 | F15: 身体反应与症状 | H15: 小于50 | I15: 大于100 | J15: 正常值
B16: 共振频率指数 （压力指数） | D16: 24490 | E16: 1000以下退行性风险 15000以上神经体系压力 | F16: 指数大于15000时，表示神经过度活跃、压力、紧张、老化、过度情绪反应，或有身体疼痛。 低于1000时，表示身体疲劳，有退行性风险。 *注意：部分孩童、有高度精神意识、自闭症的人可能在更高的频率上振动，导致数值偏高，不要惊慌。 | H16: =IF(E16<=50,E16,0) -> 0 | I16: 100 | J16: =IF(AND(E16>50,E16<100),E16,0) -> 0 | K16: Major resonant frequency of the client
B17: 欲望压力 | D17: 110 | E17: 欲望和期望造成的心理负担 | H17: =IF(D17<=50,D17,0) -> 0 | I17: =IF(D17>=100,D17,0) -> 110 | J17: =IF(AND(D17>50,D17<100),D17,0) -> 0 | K17: Desire Stress
B18: 缺乏意识 | D18: 111 | E18: 对自身健康状况认知不足 | H18: =IF(D18<=50,D18,0) -> 0 | I18: =IF(D18>=100,D18,0) -> 111 | J18: =IF(AND(D18>50,D18<100),D18,0) -> 0 | K18: Lack of Awareness
B19: 创伤 | D19: 105 | E19: 身体或心理创伤的影响 | H19: =IF(D19<=50,D19,0) -> 0 | I19: =IF(D19>=100,D19,0) -> 105 | J19: =IF(AND(D19>50,D19<100),D19,0) -> 0 | K19: Trauma
B20: 心理因素 | D20: 111 | E20: 情绪和心理状态对疾病的影响 | H20: =IF(D20<=50,D20,0) -> 0 | I20: =IF(D20>=100,D20,0) -> 111 | J20: =IF(AND(D20>50,D20<100),D20,0) -> 0 | K20: Mental Factors
B21: 自我挣扎 | D21: 61 | E21: 内心冲突和自我对抗 | H21: =IF(D21<=50,D21,0) -> 0 | I21: =IF(D21>=100,D21,0) -> 0 | J21: =IF(AND(D21>50,D21<100),D21,0) -> 61 | K21: Struggle with Self
B22: 人际关系压力 | D22: 100 | E22: 社交关系带来的压力 | H22: =IF(D22<=50,D22,0) -> 0 | I22: =IF(D22>=100,D22,0) -> 100 | J22: =IF(AND(D22>50,D22<100),D22,0) -> 0 | K22: Interpersonal Stress
B23: 家庭压力 | D23: 88 | E23: 家庭环境和关系压力 | H23: =IF(D23<=50,D23,0) -> 0 | I23: =IF(D23>=100,D23,0) -> 0 | J23: =IF(AND(D23>50,D23<100),D23,0) -> 88 | K23: Family Stress
B24: 压力 | D24: 78 | E24: 一般性压力反应 | F24: 一般性压力反应 | G24: 一般性压力反应 | H24: =IF(D24<=50,D24,0) -> 0 | I24: =IF(D24>=100,D24,0) -> 0 | J24: =IF(AND(D24>50,D24<100),D24,0) -> 78 | K24: Stress
B25: 过度思考 | D25: 47 | E25: 过度分析和担忧 | H25: =IF(D25<=50,D25,0) -> 47 | I25: =IF(D25>=100,D25,0) -> 0 | J25: =IF(AND(D25>50,D25<100),D25,0) -> 0 | K25: Overthinking
B26: 工作或学业压力 | D26: 72 | E26: 职业或学习相关压力 | F26: 职业或学习相关压力 | G26: 职业或学习相关压力 | H26: =IF(D26<=50,D26,0) -> 0 | I26: =IF(D26>=100,D26,0) -> 0 | J26: =IF(AND(D26>50,D26<100),D26,0) -> 72 | K26: Job or School Stress
B27: 健康问题导致的压力 | D27: 47 | E27: 疾病本身带来的压力 | H27: =IF(D27<=50,D27,0) -> 47 | I27: =IF(D27>=100,D27,0) -> 0 | J27: =IF(AND(D27>50,D27<100),D27,0) -> 0 | K27: Stress from Health Issues
B28: **报告说明：本报告用来评估目前身体健康的压力状态，不等同与医院和体检的检测结果，不用做诊断。

Sheet 16.神经递质
B1: 神经递质平衡性评估报告
B2: 数据总结
B3: 本类别共 47 个项目。
B4: 高反应项目(≥100): | C4: 10 | D4: 低反应项目(≤50): | E4: 8
B5: 分析建议:
B6: 反应值偏高可能表示相关系统存在压力或负担，建议关注。
B7: 有 2 个项目反应值偏低(≤50)，可能表示相关营养素或功能不足，建议适当补充或调理。
B9: 检测项目 | D9: 反应值 | E9: 检测项目 | G9: 反应值
B10: 生长抑素 | 阿片肽，生长激素的一部分，抑制生长问题。 | E10: 胸腺素 | 刺激白细胞用于免疫系统防御细菌和真菌。 | H10: SOMATOSTATIN | Opioid peptide, part of growth hormone, ids growth concern. | I10: THYMOSIN | Stimulates white blood cell for immune system defense of bacteria and fungus.
B11: GABA（γ-氨基丁酸） | 控制大脑电活动风暴的大脑因子。 | E11: 促甲状腺激素释放激素 (TSH) | 识别甲状腺疾病，训练抑郁、疲劳、自杀倾向 。 | H11: GABA (Gamma Amino Butyric Acid) | Brain factor that controls electrical storms in the brain | I11: THYROTROPIN RELEASING HORMONE (TSH) | Ids thyroid disorder, trains depression, fatigue, suicidal.
B12: 血清素 | 幸福激素，也调节损伤，失调会导致不安全感 | E12: γ球蛋白 | 用于增强免疫系统。 | H12: SEROTONIN | Happiness hormone that also regulates injury, deregulation produces insecurity | I12: GAMMA GLOBULIN | Used to increase the immune system.
B13: 血管紧张素 | 生物活性肽，与压力和血压相关的激素。 | E13: 亮氨酸脑啡肽 | 用于疼痛和情感控制的大脑激素 | H13: ANGIOTENSIN | Bioactive peptide, hormone related to stress and blood pressure. | I13: LEUCINE ENKEPHALIN | Brain hormone for pain & emotional control.
B14: DL-甲状腺素 | 主要甲状腺激素，用于刺激能量和代谢，抑制甲状腺问题。 | E14: P物质 | 负责传递疼痛感觉。 | H14: DL-THYROXINE | Major thyroid hormone for energy and metabolism stimulation, ids thyroid concern | I14: SUBSTANCE P | Responsible for communicating pain sensations.
B15: 所有下丘脑激素 | 用于所有稳态调节。 | E15: 前列腺素 | 识别炎症疾病 | H15: ALL HYPOTHALAMIC HORMONES | For all homeostasis regulation. | I15: PROSTAGLANDIN | Ids inflammation disease.
B16: 谷氨酸 | 主要兴奋性神经递质，参与学习、记忆和神经激活。 | E16: 促肾上腺皮质激素 (ACTH 促肾上腺皮质激素A) | 生物活性肽。 | H16: GLUTAMATE | Primary excitatory neurotransmitter involved in learning, memory, and neural activation. | I16: ADRENOCORTICOTROPIC HORMONE (ACTH Corticotropin A) | Bioactive peptide.
B17: 雌激素 | 调节女性生殖健康、月经周期和第二性征的激素。 | E17: 睾酮 | 男性性激素，与攻击性和易怒性相关，男性性特征。 | H17: ESTROGEN | Hormone that regulates female reproductive health, menstrual cycles, and secondary sexual characteristics. | I17: TESTOSTERONE | Male sex hormone, concern with aggression & irritabiliy, male sex characteristics.
B18: 胰岛素 | 允许葡萄糖穿透细胞膜以产生能量，关注血糖问题。 | E18: 吗啡脑啡肽 | 阿片肽。 | H18: INSULIN | Allows glucose to penetrate cell membranes for energy manufacture, concern with blood sugar dis. | I18: MORPHINE ENKAPHALIN | Opioid peptide
B19: 多巴胺 | 启动行动并调节血压和多种激素功能的激素。 | E19: 促胰液素 | 胃肠肽，识别胃肠疾病。 | H19: DOPAMINE | Hormone for starting action & regulating many functions of blood pressure and other horm. | I19: SECRETIN | Gastro intestinal peptide, ids gastro intestinal disease.
B20: 去甲肾上腺素 | 用于行动和活动的肾上腺激素，刺激交感神经系统。 | E20: 谷氨酰胺（谷氨酸） | 平衡左右的氨基酸，穿过血脑屏障，提供能量。 | H20: NOREPINEPHRINE | Adrenaline hormone for action & activity, stimulates sympathetic nervous system. | I20: GLUTAMINE (GLUTAMIC ACID) | Amino acid balances left+right, crosses blood barrier, supplies energy.
B21: 孕酮激素 | 在周期后半段由黄体产生，刺激月经，改善经前综合症。 | E21: 牛磺酸 | 用于能量控制的氨基酸。 | H21: PROGESTERONE HORMONE | Made in the corpus leutem during 2nd half of the cycle, stims. period, > PMS. | I21: TAURINE | Amino acid used for energy control.
... B32: 所有阿片类递质 | E32: 促红细胞生成素 | 生物活性肽，有助于控制贫血和血液形成。 | H32: ALL TRANSMITTERS OPIOID TYPE | I32: ERYTHROPIETIN | Bioactive peptide that helps control anemia and blood formation.
B33: 神经紧张素 | 胃肠肽，影响高血压、高血糖、肠道蠕动、循环、生长、甲状腺功能减退 | H33: NEUROTENSIN | GI peptide, affects hypertension, hyperglycemia, gut motility, circ., growth, hypothy
B34: **报告说明：本报告用来评估目前身体健康的压力状态，不等同与医院和体检的检测结果，不用做诊断。

Sheet 封底

Sheet 封底1

Sheet 封底2

Sheet 封底3

Sheet 封底4
